Workbook
Name _Div1: #REF!
Name _Div2: #REF!
Name _Div3: #REF!
Name _Div4: #REF!
Name _Regression_Int: 1
Name BaseYear: [1]Controls!$C$23
Name coup: [4]Convexity!$C$7
Name DateHeader: [1]Controls!$E$27
Name DollarHeader: [1]Controls!$E$20
Name FX: #REF!
Name g_firm: #REF!
Name IQ_CH: 110000
Name IQ_CQ: 5000
Name IQ_CY: 10000
Name IQ_DAILY: 500000
Name IQ_FH: 100000
Name IQ_FQ: 500
Name IQ_FY: 1000
Name IQ_LTM: 2000
Name IQ_MONTH: 15000
Name IQ_NTM: 6000
Name IQ_WEEK: 50000
Name IQ_YTD: 3000
Name k: #REF!
Name k_eq: #REF!
Name mat: [4]Convexity!$C$9
Name price: [4]Convexity!$C$10
Name Price4: #REF!
Name Print_Area_MI: #REF!
Name rdebt: #REF!
Name Selling_Price: '[5]Base Case'!$B$11
Name tax_rate: #REF!
Name taxtable: #REF!
Name term_g: #REF!
Name Variable_Cost_per_unit: '[5]Base Case'!$B$12
Name WACC_5: #REF!
Name ytm: [4]Convexity!$C$8

Sheet ROE & Growth
B7: Part I. DDM w/ Dividend Growth
B9: as of 9/23/2024, (ttm: trailing 12 months) | C9: Stock A | D9: Stock B
B10: Discount rate | C10: 0.07 | D10: 0.07
B11: Return on equity at year 1 | C11: 0.15 | D11: 0.18
B12: Earnings per share at year 1 | C12: =3.35*(1+0.0587) -> 3.546645 | D12: 4
B13: Dividends per share at year 1 | C13: =2.04*(1.0587) -> 2.159748 | D13: =2*1.04 -> 2.08
B14: a. Dividend payout ratio | C14: =C13/C12 -> 0.60895522 | D14: =D13/D12 -> 0.52 | E14: =_xlfn.FORMULATEXT(D14) -> =D13/D12
B15: b. Expected dividend growth | C15: =(1-C14)*C11 -> 0.058656716 | D15: =D11*(1-D14) -> 0.0864 | E15: =_xlfn.FORMULATEXT(D15) -> =D11*(1-D14)
B16: c. Stock value today | C16: =C13/(C10-C15) -> 190.39884 | D16: =-(D13/(D10-D15)) -> 126.82927 | E16: =_xlfn.FORMULATEXT(D16) -> =-(D13/(D10-D15))
B17: Payout Ratio (PR, % Distribution of profit) = Dividend1 / Net Income1 (or EPS1)
B18: Expected growth rate (%) = Return on Equity x (1 – Payout Ratio)
B19: PVcs = D1 / (r – g)
B21: Part II. DDM w/ Return on Equity & P/E, P/B ratio
B23: a. when ROE is 15% | E23: b. when ROE is 18%
B24: Return on equity (%) | C24: =15% -> 0.15 | D24: =_xlfn.FORMULATEXT(C24) -> =15% | E24: Return on equity (%) | F24: =18% -> 0.18 | G24: =_xlfn.FORMULATEXT(F24) -> =18% | I24: Return on Equity (ROE, %) = Net Income1 / Equity
B25: Plowback(Retention) ratio (%) | C25: =39.1% -> 0.391 | D25: =_xlfn.FORMULATEXT(C25) -> =39.1% | E25: Plowback(Retention) ratio (%) | F25: =36.1% -> 0.361 | G25: =_xlfn.FORMULATEXT(F25) -> =36.1%
B26: g (%) | C26: =C24*C25 -> 0.05865 | D26: =_xlfn.FORMULATEXT(C26) -> =C24*C25 | E26: g (%) | F26: =6.05% -> 0.0605 | G26: =_xlfn.FORMULATEXT(F26) -> =6.05% | I26: growth (g, %) = Return on Equity x Retention Ratio = Return on Equity x (1 – Payout Ratio)
B27: Discount rate (%) | C27: =7% -> 0.07 | D27: =_xlfn.FORMULATEXT(C27) -> =7% | E27: Discount rate (%) | F27: =C27 -> 0.07 | G27: =_xlfn.FORMULATEXT(F27) -> =C27
B28: BV of equity beginning balance ($, million) | C28: =24856 -> 24856 | D28: =_xlfn.FORMULATEXT(C28) -> =24856 | E28: BV of equity beginning balance ($, million) | F28: =C28 -> 24856 | G28: =_xlfn.FORMULATEXT(F28) -> =C28
B29: + Earnings or net Income of the year ($, million) | C29: =C28*C24 -> 3728.4 | D29: =_xlfn.FORMULATEXT(C29) -> =C28*C24 | E29: + Earnings or net Income of the year ($, million) | F29: =F28*F24 -> 4474.08 | G29: =_xlfn.FORMULATEXT(F29) -> =F28*F24 | I29: Net Income = Equity x Return on Equity
B30: - Dividends of the year ($, million) | C30: =C29*(1-C25) -> 2270.5956 | D30: =_xlfn.FORMULATEXT(C30) -> =C29*(1-C25) | E30: - Dividends of the year ($, million) | F30: =F29*(1-F25) -> 2858.9371 | G30: =_xlfn.FORMULATEXT(F30) -> =F29*(1-F25) | I30: Dividend1 = Net Income1 x Payout Ratio = Net Income1 x (1 - Retention Ratio)
B31: = BV of equity ending balance ($, million) | C31: =C28+C29-C30 -> 26313.804 | D31: =_xlfn.FORMULATEXT(C31) -> =C28+C29-C30 | E31: = BV of equity ending balance ($, million) | F31: =F28+F29-F30 -> 26471.143 | G31: =_xlfn.FORMULATEXT(F31) -> =F28+F29-F30 | I31: BV of Equity ending balance = BV of Equity beginning balance + net income - dividend
B32: Market value by DDM ($, million) | C32: =C30/(C27-C26) -> 200052.48 | D32: =_xlfn.FORMULATEXT(C32) -> =C30/(C27-C26) | E32: Market value by DDM ($, million) | F32: =F30/(F27-F26) -> 300940.75 | G32: =_xlfn.FORMULATEXT(F32) -> =F30/(F27-F26) | I32: PVcs = D1 / (r – g)
B33: P/E ratio | C33: =C32/C29 -> 53.656388 | D33: =_xlfn.FORMULATEXT(C33) -> =C32/C29 | E33: P/E ratio | F33: =F32/F29 -> 67.263158 | G33: =_xlfn.FORMULATEXT(F33) -> =F32/F29 | I33: P/E = Market Value / Earnings
B34: P/B ratio | C34: =C32/C28 -> 8.0484581 | D34: =_xlfn.FORMULATEXT(C34) -> =C32/C28 | E34: P/B ratio | F34: =F32/F28 -> 12.107368 | G34: =_xlfn.FORMULATEXT(F34) -> =F32/F28 | I34: P/B = Market Value / Book Value of Equity
B37: Part III. DDM Application to Coca-Cola
B39: as of 9/23/2024, (ttm: trailing 12 months) | C39: KO
B40: Discount rate (Cost of Equity by CAPM) | C40: =7% -> 0.07 | D40: =_xlfn.FORMULATEXT(C40) -> =7%
B41: Return on equity (%) | C41: =15% -> 0.15 | D41: =_xlfn.FORMULATEXT(C41) -> =15%
B42: Earnings per share ($) | C42: =3.35 -> 3.35 | D42: =_xlfn.FORMULATEXT(C42) -> =3.35
B43: Dividends per share ($) | C43: =2.04 -> 2.04 | D43: =_xlfn.FORMULATEXT(C43) -> =2.04
B44: Dividend payout ratio (%) | C44: =C43/C42 -> 0.60895522 | D44: =_xlfn.FORMULATEXT(C44) -> =C43/C42
B45: Expected dividend growth (%) | C45: =C41*(1-C44) -> 0.058656716 | D45: =_xlfn.FORMULATEXT(C45) -> =C41*(1-C44)
B46: Intrinsic Stock Value today by DDM ($) | C46: =C43/(C40-C45) -> 179.84211 | D46: =_xlfn.FORMULATEXT(C46) -> =C43/(C40-C45)
B47: Stock Price today ($) | C47: 70.52
B48: Expected Rate of Return (%) | C48: =((C43*(1+C45))/C47)+C45 -> 0.089281499 | D48: =_xlfn.FORMULATEXT(C48) -> =((C43*(1+C45))/C47)+C45
B49: Buy / Hold / Sell | C49: Hold
B53: Source: https://finance.yahoo.com/quote/KO/

Sheet DDM Nonconstant g
B7: Intrinsic Value of Equity by DDM
B9: A. Projected years by DDM ($ in million) | C9: 2024 | D9: 2025 | E9: 2026 | F9: 2027 | G9: 2029
B10: Book Value of Equity (beginning balance) | C10: ='ROE & Growth'!C28 -> 24856 | D10: =C13 -> 30498 | E10: =D13 -> 32022.9 | F10: =E13 -> 33624.045 | G10: =F13 -> 35305.247 | H10: =_xlfn.FORMULATEXT(C10) -> ='ROE & Growth'!C28 | I10: =_xlfn.FORMULATEXT(D10) -> =C13 | J10: =_xlfn.FORMULATEXT(E10) -> =D13 | K10: =_xlfn.FORMULATEXT(F10) -> =E13 | L10: =_xlfn.FORMULATEXT(G10) -> =F13
B11: Earnings (Net Income) of the year | C11: =14448 -> 14448 | D11: =D10*20% -> 6099.6 | E11: =E10*20% -> 6404.58 | F11: =F10*20% -> 6724.809 | G11: =G10*20% -> 7061.0495 | H11: =_xlfn.FORMULATEXT(C11) -> =14448 | I11: =_xlfn.FORMULATEXT(D11) -> =D10*20% | J11: =_xlfn.FORMULATEXT(E11) -> =E10*20% | K11: =_xlfn.FORMULATEXT(F11) -> =F10*20% | L11: =_xlfn.FORMULATEXT(G11) -> =G10*20%
B12: Dividends of the year | C12: =8806 -> 8806 | D12: =D11*75% -> 4574.7 | E12: =E11*75% -> 4803.435 | F12: =F11*75% -> 5043.6067 | G12: =G11*75% -> 5295.7871 | H12: =_xlfn.FORMULATEXT(C12) -> =8806 | I12: =_xlfn.FORMULATEXT(D12) -> =D11*75% | J12: =_xlfn.FORMULATEXT(E12) -> =E11*75% | K12: =_xlfn.FORMULATEXT(F12) -> =F11*75% | L12: =_xlfn.FORMULATEXT(G12) -> =G11*75%
B13: Book Value of Equity (ending balance) | C13: =C10+C11-C12 -> 30498 | D13: =D10+D11-D12 -> 32022.9 | E13: =E10+E11-E12 -> 33624.045 | F13: =F10+F11-F12 -> 35305.247 | G13: =G10+G11-G12 -> 37070.51 | H13: =_xlfn.FORMULATEXT(C13) -> =C10+C11-C12 | I13: =_xlfn.FORMULATEXT(D13) -> =D10+D11-D12 | J13: =_xlfn.FORMULATEXT(E13) -> =E10+E11-E12 | K13: =_xlfn.FORMULATEXT(F13) -> =F10+F11-F12 | L13: =_xlfn.FORMULATEXT(G13) -> =G10+G11-G12
B14: Permanent Value
A15: + | B15: Total Free Cash Flows by DDM | C15: =C12+C14 -> 8806 | D15: =D12+D14 -> 4574.7 | E15: =E12+E14 -> 4803.435 | F15: =F12+F14 -> 5043.6067 | G15: =G12+G14 -> 5295.7871 | H15: =_xlfn.FORMULATEXT(C15) -> =C12+C14 | I15: =_xlfn.FORMULATEXT(D15) -> =D12+D14 | J15: =_xlfn.FORMULATEXT(E15) -> =E12+E14 | K15: =_xlfn.FORMULATEXT(F15) -> =F12+F14 | L15: =_xlfn.FORMULATEXT(G15) -> =G12+G14
A16: -
A17: = | B17: B. Stock Valuation by DDM
B18: Permanent Growth Rate of Dividend after year 2024 (%) | C18: =20%*(1-65%) -> 0.07 | D18: =_xlfn.FORMULATEXT(C18) -> =20%*(1-65%)
B19: Intrinsic Value of the equity by DDM ($ in million) | C19: =NPV(C18,C15:G15) -> 23770.227 | D19: =_xlfn.FORMULATEXT(C19) -> =NPV(C18,C15:G15)

Sheet EX. DDM Basics
B7: Part I. Discount Dividend Model.
B9: a. What price based on DDM should the stock sell at if the discount rate is 15%?
B10: Current Price. PVcs = D1 / (r – g) | C10: ='ROE & Growth'!C13/('ROE & Growth'!C11-'ROE & Growth'!C15) -> 23.6443 | D10: =_xlfn.FORMULATEXT(C10) -> ='ROE & Growth'!C13/('ROE & Growth'!C11-'ROE & Growth'!C15)
B12: b. What price based on DDM should the stock sell at if the discount rate is 18%.
B13: Current Price | C13: ='ROE & Growth'!C13/('ROE & Growth'!D11-'ROE & Growth'!D15) -> 23.074231 | D13: =_xlfn.FORMULATEXT(C13) -> ='ROE & Growth'!C13/('ROE & Growth'!D11-'ROE & Growth'!D15)
B15: Part II. Stock Price with Permanent Value
B17: Input Data.
B18: Growth rate for Years 1-3 | C18: 0.06
B19: Last dividend paid | C19: 2.04
B20: Discount rate | C20: 0.07
B21: Growth rate after 3 years | C21: 0.05
B23: Year 0 | C23: 1 | D23: 2 | E23: 3
B24: Dividends | C24: =C19*(1+C18) -> 2.1624 | D24: =C24*(1+C18) -> 2.292144 | E24: =D24*(1+C18) -> 2.4296726 | F24: =_xlfn.FORMULATEXT(E24) -> =D24*(1+C18)
B25: Terminal Value at year 3 end | E25: =(E24*(1+C21))/(C20-C21) -> 127.55781 | F25: =_xlfn.FORMULATEXT(E25) -> =(E24*(1+C21))/(C20-C21)
B26: Total Cash Flows | C26: =C24 -> 2.1624 | D26: =D24 -> 2.292144 | E26: =SUM(E24:E25) -> 129.98749
B27: Dividend Stock price PV0 | C27: =_xlfn.FORMULATEXT(C26) -> =C24 | D27: =_xlfn.FORMULATEXT(D26) -> =D24 | E27: =_xlfn.FORMULATEXT(E26) -> =SUM(E24:E25) | G27: PV3 = DIV4 / (r – g)
B28: =NPV(C20,C26,D26,E26) -> 110.13149
B29: =_xlfn.FORMULATEXT(B28) -> =NPV(C20,C26,D26,E26)
B31: Part III. Preferred Stock Valuation
B33: Input variables:
B34: Annual dividend | C34: 3
B35: Discount rate (Required Rate of Return) | C35: 0.12
B37: a. If the discount rate is 12%, at what price should the preferred sell?
B38: Price0. PV of preferred stock = D / r | C38: =C34/C35 -> 25 | D38: =_xlfn.FORMULATEXT(C38) -> =C34/C35
B40: b. At what price should the stock sell 1 year from now?
B41: Price1 | C41: =C38 -> 25 | D41: =_xlfn.FORMULATEXT(C41) -> =C38
B43: c. What is the dividend yield, the capital gains yield, and the required rate of return of the stock?
B44: Required rate of return = Dividend Yield + Capital Yield | C44: =C35 -> 0.12 | D44: =_xlfn.FORMULATEXT(C44) -> =C35
B45: Dividend yield = D/Price | C45: =C34/C41 -> 0.12 | D45: =_xlfn.FORMULATEXT(C45) -> =C34/C41
B46: Capital yield = Required rate of return - Dividend Yield | C46: =(C38-C41)/C41 -> 0 | D46: =_xlfn.FORMULATEXT(C46) -> =(C38-C41)/C41
B49: Part IV. Yields. Income Gain and Capital Gain in DDM Model
B50: Input data.
B51: Annual growth rate | C51: ='ROE & Growth'!C15 -> 0.058656716
B52: Required return | C52: ='ROE & Growth'!C10 -> 0.07
B53: DIV1 | C53: =C24 -> 2.1624
B55: a. what is the value of a share today?
B56: Value of a share | C56: =C53/(C52-C51) -> 190.63263 | D56: =_xlfn.FORMULATEXT(C56) -> =C53/(C52-C51) | E56: PVcs = D1 / (r – g)
B58: b. What price do you forecast for the stock next year?
B59: Stock price | C59: ='ROE & Growth'!C47*(1+'EX. DDM Basics'!C51) -> 74.656472 | D59: =_xlfn.FORMULATEXT(C59) -> ='ROE & Growth'!C47*(1+'EX. DDM Basics'!C51) | E59: PVcs = D1 / (r – g)
B61: c. What rate of return should you expect if you buy the stock today and sell it in one year?
...
