Workbook
Name BaseYear: [1]Controls!$C$23
Name DateHeader: [1]Controls!$E$27
Name DollarHeader: [1]Controls!$E$20
Name FX: #REF!
Name Selling_Price: '[4]Base Case'!$B$11
Name taxtable: #REF!
Name Variable_Cost_per_unit: '[4]Base Case'!$B$12

Sheet General Info
G3: General Information
B8: Table of Contents
B9: 1 | C9: Tear Sheet
B10: =+B9+1 -> 2 | C10: =Summary!F3 -> Valuation Summary
B11: =+B10+1 -> 3 | C11: ='Actuals FS'!D3 -> Historic Financial Statements
B12: =+B11+1 -> 4 | C12: ='HWMS Model'!F2 -> AMZN Quarterly Sales Forecasting: Holt-Winters Multiplicative Seasonal (HWMS) Model
B13: =+B12+1 -> 5 | C13: =Revenue!D2 -> Revenue Breakdown & Projections
B14: =+B13+1 -> 6 | C14: =Scenarios!C3 -> Scenario Assumptions
B15: =+B14+1 -> 7 | C15: =Multiples!C3 -> Relative Multiples Valuation Model Based on Selected Industry Peers
B16: =+B15+1 -> 8 | C16: ='Forecasted FS'!C3 -> Forecasted Financial Statements
B17: =+B16+1 -> 9 | C17: =WACC!B3 -> Weighted Average Cost of Capital
B18: =+B17+1 -> 10 | C18: =DCF!C3 -> Discounted Cash Flows Model
B19: =+B18+1 -> 11 | C19: =References!B7 -> References
B21: Appendix
B22: =Appendix!B8 -> 1 | C22: =Appendix!C8 -> Financial Statements
B23: =Appendix!B9 -> 2 | C23: =Appendix!C9 -> Financial Ratios Analysis
B24: =Appendix!B10 -> 3 | C24: =Appendix!C10 -> Operating Margin Target Based on Management Expectations
B25: =Appendix!B11 -> 4 | C25: =Appendix!C11 -> Depreciation & Amortization Schedule
B26: =Appendix!B12 -> 5 | C26: =Appendix!C12 -> Summary of Corporate Bonds
B27: =Appendix!B13 -> 6 | C27: =Appendix!C13 -> Scenario Summary
B28: =Appendix!B14 -> 7 | C28: =Appendix!C14 -> Industry Peers Market Information
B29: =Appendix!B15 -> 8 | C29: =Appendix!C15 -> Industry Peers Financial Information
B30: =Appendix!B16 -> 9 | C30: =Appendix!C16 -> 10 year Historic S&P Returns
B31: =Appendix!B17 -> 10 | C31: =Appendix!C17 -> AMZN Historic Daily Stock Prices from 12/12/205 to date (12/12/2025)
B32: =Appendix!B18 -> 11 | C32: =Appendix!C18 -> 10 year Historic Yield to Maturity of US 10 year Treasury Bill
B33: =Appendix!B19 -> 12 | C33: =Appendix!C19 -> Country Corporate Income Tax Rate
... B38: =Appendix!B24 -> 17 | C38: =Appendix!C24 -> Abbreviations
B40: General information for the reader:
B41: - Forward looking statements were elaborated by the author for academic purposes
B42: - Assumptions made are referenced in each tab under "NOTES"
B43: - This report serves as supporting evidence to the written report that exhibits the authors conclusions and insights

Sheet Tear Sheet
B8: Recommendation: | C8: BUY | D8: Price: | E8: ='AMZN daily'!G8 -> 226.19 | G8: (12/12/2025) | J8: Target Price: | K8: =DCF!I49 -> 292.99442
B11: GICS Sector: Consumer Discretionary | D11: Business Summary: Amazon is a global leader in e-commerce, cloud computing, online advertising, digital streaming, and artificial intelligence.
B12: Sub-Sector: Broadline Retail
B13: NAICS Industry: Electronic Shopping
C14: and Mail-Order Houses
B16: Key Stock Statistics
B18: Market Capitalization (BN) | C18: 2418.02 | D18: 52-Week Range | G18: =MIN('AMZN daily'!G8:G245) -> 167.32 | H18: =MAX('AMZN daily'!G8:G245) -> 254 | I18: Year Founded | K18: 1994
B19: Enterprise Value (BN) | C19: 2511.5 | D19: Shares Outstanding (M) | H19: ='Actuals FS'!D68 -> 10721 | I19: Inst. Ownership (%) | K19: =Shareholders!D16 -> 0.7522
B20: FY 2024 EPS | C20: =7.08 -> 7.08 | D20: Avg. Volume ('000) | H20: =AVERAGE('AMZN daily'!I8:I1086)/1000 -> 43002.979 | I20: Rating (S&P/Moody's) | K20: AA/A1
B21: FY 2024P/E | C21: =E8/C20 -> 31.94774 | D21: Dividend per share | H21: ='Actuals FS'!D145 -> 0 | I21: Unlevered Beta | K21: =WACC!E21 -> 1.354696
B22: FY 2024 P/Sales | C22: =C18/('Actuals FS'!D47/1000) -> 3.7902436 | D22: Dividend Yield (%) | H22: =H21/E8 -> 0 | I22: Levered Beta | K22: =WACC!E22 -> 1.3772792
B24: Price Performance (NYS: AMZN)
B40: Financial Summary
B42: In $ millions | C42: ='FS all'!D10 -> 2020 A | D42: ='FS all'!E10 -> 2021 A | E42: ='FS all'!F10 -> 2022 A | F42: ='FS all'!G10 -> 2023 A | G42: ='FS all'!H10 -> 2024 A | H42: ='FS all'!I10 -> 2025 F | I42: ='FS all'!J10 -> 2026 F | J42: ='FS all'!K10 -> 2027 F | ... L42: ='FS all'!M10 -> 2029 F
B43: Revenues | C43: ='FS all'!D11 -> 386064 | D43: ='FS all'!E11 -> 469822 | E43: ='FS all'!F11 -> 513983 | F43: ='FS all'!G11 -> 574785 | G43: ='FS all'!H11 -> 637959 | H43: ='FS all'!I11 -> 682616.13 | I43: ='FS all'!J11 -> 744051.58 | J43: ='FS all'!K11 -> 811016.22 | ... L43: ='FS all'!M11 -> 981329.63
B44: EBITDA | C44: ='FS all'!D153 -> 42001 | D44: ='FS all'!E153 -> 61197 | E44: ='FS all'!F153 -> 40049 | F44: ='FS all'!G153 -> 68786 | G44: ='FS all'!H153 -> 100372 | H44: ='FS all'!I153 -> 103809.96 | I44: ='FS all'!J153 -> 120800.59 | J44: ='FS all'!K153 -> 136973.97 | ... L44: ='FS all'!M153 -> 172734.73
B45: Net Income | C45: ='FS all'!D30 -> 21331 | D45: ='FS all'!E30 -> 33364 | E45: ='FS all'!F30 -> -2722 | F45: ='FS all'!G30 -> 30425 | G45: ='FS all'!H30 -> 59248 | H45: ='FS all'!I30 -> 66748.877 | I45: ='FS all'!J30 -> 84364.915 | J45: ='FS all'!K30 -> 100964.18 | ... L45: ='FS all'!M30 -> 139417.22
B46: Total Assets | C46: ='FS all'!D47 -> 321195 | D46: ='FS all'!E47 -> 420549 | E46: ='FS all'!F47 -> 462675 | F46: ='FS all'!G47 -> 527854 | G46: ='FS all'!H47 -> 624894 | H46: ='FS all'!I47 -> 737028.24 | I46: ='FS all'!J47 -> 873770.46 | J46: ='FS all'!K47 -> 1027375.5 | ... L46: ='FS all'!M47 -> 1405539.8
B47: Total Debt | C47: ='FS all'!D55 -> 31816 | D47: ='FS all'!E55 -> 48744 | E47: ='FS all'!F55 -> 67150 | F47: ='FS all'!G55 -> 58314 | G47: ='FS all'!H55 -> 52623 | H47: ='FS all'!I55 -> 57214 | I47: ='FS all'!J55 -> 61805 | J47: ='FS all'!K55 -> 64100.5 | ... L47: ='FS all'!M55 -> 65822.125
B48: Equity | C48: ='FS all'!D67 -> 93404 | D48: ='FS all'!E67 -> 138245 | E48: ='FS all'!F67 -> 146043 | F48: ='FS all'!G67 -> 201875 | G48: ='FS all'!H67 -> 285970 | H48: ='FS all'!I67 -> 374263.03 | I48: ='FS all'!J67 -> 480525.78 | J48: ='FS all'!K67 -> 603747.28 | ... L48: ='FS all'!M67 -> 908851.28
B50: Key Financial Indicators
B52: EBITDA Margin (%) | C52: ='FS all'!D154 -> 0.10879284 | D52: ='FS all'!E154 -> 0.13025571 | E52: ='FS all'!F154 -> 0.077918919 | F52: ='FS all'!G154 -> 0.11967257 | G52: ='FS all'!H154 -> 0.15733299 | H52: ='FS all'!I154 -> 0.15207662 | I52: ='FS all'!J154 -> 0.16235512 | J52: ='FS all'!K154 -> 0.16889178 | ... L52: ='FS all'!M154 -> 0.17602111
B53: Operating Margin (%) | C53: ='FS all'!D119 -> 0.059314 | D53: ='FS all'!E119 -> 0.052954098 | E53: ='FS all'!F119 -> 0.023829582 | F53: ='FS all'!G119 -> 0.064114408 | G53: ='FS all'!H119 -> 0.10751945 | H53: ='FS all'!I119 -> 0.12336577 | I53: ='FS all'!J119 -> 0.14312706 | J53: ='FS all'!K119 -> 0.15719767 | ... L53: ='FS all'!M119 -> 0.17953858
B54: Debt to Equity (x) | C54: =('FS all'!D55/'FS all'!D67) -> 0.34062781 | D54: =('FS all'!E55/'FS all'!E67) -> 0.35259141 | E54: =('FS all'!F55/'FS all'!F67) -> 0.45979609 | F54: =('FS all'!G55/'FS all'!G67) -> 0.28886192 | G54: =('FS all'!H55/'FS all'!H67) -> 0.18401581 | H54: =('FS all'!I55/'FS all'!I67) -> 0.1528711 | I54: =('FS all'!J55/'FS all'!J67) -> 0.12861953 | J54: =('FS all'!K55/'FS all'!K67) -> 0.10617108 | ... L54: =('FS all'!M55/'FS all'!M67) -> 0.072423427
B55: ROE (%) | C55: ='FS all'!D137 -> 0.22837352 | D55: ='FS all'!E137 -> 0.24133965 | E55: ='FS all'!F137 -> -0.018638346 | F55: ='FS all'!G137 -> 0.15071207 | G55: ='FS all'!H137 -> 0.20718257 | H55: ='FS all'!I137 -> 0.1930318 | I55: ='FS all'!J137 -> 0.19047206 | J55: ='FS all'!K137 -> 0.18074065 | ... L55: ='FS all'!M137 -> 0.16516639
B56: ROA (%) | C56: ='FS all'!D120 -> 0.06641137 | D56: ='FS all'!E120 -> 0.079334394 | E56: ='FS all'!F120 -> -0.0058831793 | F56: ='FS all'!G120 -> 0.057639044 | G56: ='FS all'!H120 -> 0.09481288 | H56: ='FS all'!I120 -> 0.098021568 | I56: ='FS all'!J120 -> 0.10474917 | J56: ='FS all'!K120 -> 0.10621402 | ... L56: ='FS all'!M120 -> 0.10680002
B57: ROIC (%) | C57: ='FS all'!D123 -> 0.10810323 | D57: ='FS all'!E123 -> 0.088053842 | E57: ='FS all'!F123 -> 0.03622841 | F57: ='FS all'!G123 -> 0.087275703 | G57: ='FS all'!H123 -> 0.12983255 | H57: ='FS all'!I123 -> 0.17278183 | I57: ='FS all'!J123 -> 0.17278603 | J57: ='FS all'!K123 -> 0.1664498 | ... L57: ='FS all'!M123 -> 0.15583335
B58: EPS | C58: ='FS all'!D140 -> 41.82549 | D58: ='FS all'!E140 -> 64.784466 | E58: ='FS all'!F140 -> -0.26715085 | F58: ='FS all'!G140 -> 2.8998284 | G58: ='FS all'!H140 -> 5.5263502 | H58: ='FS all'!I140 -> 6.1254358 | I58: ='FS all'!J140 -> 7.6169874 | J58: ='FS all'!K140 -> 8.9684418 | ... L58: ='FS all'!M140 -> 11.987338
B59: Dividend Per Share | C59: ='FS all'!D142 -> 0 | D59: ='FS all'!E142 -> 0 | E59: ='FS all'!F142 -> 0 | F59: ='FS all'!G142 -> 0 | G59: ='FS all'!H142 -> 0 | H59: ='FS all'!I142 -> 0 | I59: ='FS all'!J142 -> 0 | J59: ='FS all'!K142 -> 0 | ... L59: ='FS all'!M142 -> 0

Sheet Summary
F3: Valuation Summary
F4: Figures in USD millions, unless told otherwise
C8: Recommendation | E8: BUY
C10: Current Price | E10: =DCF!E14 -> 226.19
C11: Target Price | E11: =DCF!I49 -> 292.99442
C12: Expected Return (%) | E12: =E11/E10-1 -> 0.29534647
C14: Shares Outstanding (M) | E14: =DCF!E15 -> 10721
C15: Market Capitalization (B) | E15: =(E10*E14)/1000 -> 2424.983
C16: 52-Week High | E16: ='Tear Sheet'!H18 -> 254
C17: 52-Week Low | E17: ='Tear Sheet'!G18 -> 167.32
C18: Earnings Per Share | E18: ='Tear Sheet'!C20 -> 7.08
C19: Price / Earnings | E19: ='Tear Sheet'!C21 -> 31.94774
C22: CAT Valuation summary from different methods
F24: Price per Share | K24: Equity Value | P24: Enterprise Value
D25: Valuation Method | F25: Low | G25: Median | H25: Mean | I25: High | K25: Low | L25: Median | M25: Mean | N25: High | P25: Low | Q25: Median | R25: Mean | S25: High
C26: 1 | D26: 52 Week Market High/Low | F26: =MIN('AMZN daily'!H3079:H3330) -> 24.1 | G26: =MEDIAN('AMZN daily'!H3079:H3330) -> 35.89 | H26: =AVERAGE('AMZN daily'!H3079:H3330) -> 34.730119 | I26: =MAX('AMZN daily'!H3079:H3330) -> 42.22 | K26: =F26*DCF!$E$15 -> 258376.1 | L26: =G26*DCF!$E$15 -> 384776.69 | M26: =H26*DCF!$E$15 -> 372341.61 | N26: =I26*DCF!$E$15 -> 452640.62 | P26: =K26+SUM(DCF!$E$44:$E$46) -> 857114.1 | Q26: =L26+SUM(DCF!$E$44:$E$46) -> 983514.69 | R26: =M26+SUM(DCF!$E$44:$E$46) -> 971079.61 | S26: =N26+SUM(DCF!$E$44:$E$46) -> 1051378.6
C27: =C26+1 -> 2 | D27: Base Discounted Cash Flow | F27: =DCF!$E$64 -> 184.16499 | G27: =DCF!$I$63 -> 292.99442 | H27: =DCF!$I$64 -> 318.23482 | I27: =DCF!$E$63 -> 628.85346 | K27: =F27*DCF!$E$15 -> 1974432.9 | L27: =G27*DCF!$E$15 -> 3141193.2 | M27: =H27*DCF!$E$15 -> 3411795.5 | N27: =I27*DCF!$E$15 -> 6741938 | P27: =K27+SUM(DCF!$E$44:$E$46) -> 2573170.9 | Q27: =L27+SUM(DCF!$E$44:$E$46) -> 3739931.2 | R27: =M27+SUM(DCF!$E$44:$E$46) -> 4010533.5 | S27: =N27+SUM(DCF!$E$44:$E$46) -> 7340676
C28: =C27+1 -> 3 | D28: Bull Discounted Cash Flow | F28: 163.15539 | G28: 291.61809 | H28: 333.37732 | I28: 823.84708 | K28: =F28*DCF!$E$15 -> 1749188.9 | L28: =G28*DCF!$E$15 -> 3126437.5 | M28: =H28*DCF!$E$15 -> 3574138.3 | N28: =I28*DCF!$E$15 -> 8832464.6 | P28: =K28+SUM(DCF!$E$44:$E$46) -> 2347926.9 | Q28: =L28+SUM(DCF!$E$44:$E$46) -> 3725175.5 | R28: =M28+SUM(DCF!$E$44:$E$46) -> 4172876.3 | S28: =N28+SUM(DCF!$E$44:$E$46) -> 9431202.6
C29: =C28+1 -> 4 | D29: Bear Discounted Cash Flow | F29: 116.74016 | G29: 212.05019 | H29: 242.89204 | I29: 605.52322 | K29: =F29*DCF!$E$15 -> 1251571.3 | L29: =G29*DCF!$E$15 -> 2273390.1 | M29: =H29*DCF!$E$15 -> 2604045.5 | N29: =I29*DCF!$E$15 -> 6491814.5 | P29: =K29+SUM(DCF!$E$44:$E$46) -> 1850309.3 | Q29: =L29+SUM(DCF!$E$44:$E$46) -> 2872128.1 | R29: =M29+SUM(DCF!$E$44:$E$46) -> 3202783.5 | S29: =N29+SUM(DCF!$E$44:$E$46) -> 7090552.5
C30: =C29+1 -> 5 | D30: EV/Sales | F30: {=TRANSPOSE(Multiples!R49:R52)} -> -44.41795 | G30: 483.26296 | H30: 331.15663 | I30: 656.07723 | K30: =F30*DCF!$E$15 -> -476204.84 | L30: =G30*DCF!$E$15 -> 5181062.1 | M30: =H30*DCF!$E$15 -> 3550330.3 | N30: =I30*DCF!$E$15 -> 7033804 | P30: =K30+SUM(DCF!$E$44:$E$46) -> 122533.16 | Q30: =L30+SUM(DCF!$E$44:$E$46) -> 5779800.1 | R30: =M30+SUM(DCF!$E$44:$E$46) -> 4149068.3 | S30: =N30+SUM(DCF!$E$44:$E$46) -> 7632542
C31: =C30+1 -> 6 | D31: EV/EBIT | F31: {=TRANSPOSE(Multiples!S49:S52)} -> -47.928597 | G31: 128.68395 | H31: 101.11661 | I31: 174.88787 | K31: =F31*DCF!$E$15 -> -513842.49 | L31: =G31*DCF!$E$15 -> 1379620.6 | M31: =H31*DCF!$E$15 -> 1084071.2 | N31: =I31*DCF!$E$15 -> 1874972.9 | P31: =K31+SUM(DCF!$E$44:$E$46) -> 84895.509 | Q31: =L31+SUM(DCF!$E$44:$E$46) -> 1978358.6 | R31: =M31+SUM(DCF!$E$44:$E$46) -> 1682809.2 | S31: =N31+SUM(DCF!$E$44:$E$46) -> 2473710.9
C32: =C31+1 -> 7 | D32: EV/EBITDA | F32: {=TRANSPOSE(Multiples!T49:T52)} -> -48.150495 | G32: 79.130389 | H32: 66.155933 | I32: 131.51332 | K32: =F32*DCF!$E$15 -> -516221.45 | L32: =G32*DCF!$E$15 -> 848356.9 | M32: =H32*DCF!$E$15 -> 709257.75 | N32: =I32*DCF!$E$15 -> 1409954.3 | P32: =K32+SUM(DCF!$E$44:$E$46) -> 82516.548 | Q32: =L32+SUM(DCF!$E$44:$E$46) -> 1447094.9 | R32: =M32+SUM(DCF!$E$44:$E$46) -> 1307995.8 | S32: =N32+SUM(DCF!$E$44:$E$46) -> 2008692.3
C33: =C32+1 -> 8 | D33: P/E | F33: {=TRANSPOSE(Multiples!U49:U52)} -> 16.772007 | G33: 190.68812 | H33: 116.41484 | I33: 261.38465 | K33: =F33*DCF!$E$15 -> 179812.69 | L33: =G33*DCF!$E$15 -> 2044367.3 | M33: =H33*DCF!$E$15 -> 1248083.5 | N33: =I33*DCF!$E$15 -> 2802304.8 | P33: =K33+SUM(DCF!$E$44:$E$46) -> 778550.69 | Q33: =L33+SUM(DCF!$E$44:$E$46) -> 2643105.3 | R33: =M33+SUM(DCF!$E$44:$E$46) -> 1846821.5 | S33: =N33+SUM(DCF!$E$44:$E$46) -> 3401042.8
C34: Low | F34: =MIN(F26:F33) -> -48.150495 | G34: =MIN(G26:G33) -> 35.89 | H34: =MIN(H26:H33) -> 34.730119 | I34: =MIN(I26:I33) -> 42.22 | K34: =MIN(K26:K33) -> -516221.45 | L34: =MIN(L26:L33) -> 384776.69 | M34: =MIN(M26:M33) -> 372341.61 | N34: =MIN(N26:N33) -> 452640.62 | P34: =MIN(P26:P33) -> 82516.548 | Q34: =MIN(Q26:Q33) -> 983514.69 | R34: =MIN(R26:R33) -> 971079.61 | S34: =MIN(S26:S33) -> 1051378.6
C35: Median | F35: =MEDIAN(F26:F33) -> 20.436004 | G35: =MEDIAN(G26:G33) -> 201.36915 | H35: =MEDIAN(H26:H33) -> 179.65344 | I35: =MEDIAN(I26:I33) -> 433.45393 | K35: =MEDIAN(K26:K33) -> 219094.39 | L35: =MEDIAN(L26:L33) -> 2158878.7 | M35: =MEDIAN(M26:M33) -> 1926064.5 | N35: =MEDIAN(N26:N33) -> 4647059.6 | P35: =MEDIAN(P26:P33) -> 817832.39 | Q35: =MEDIAN(Q26:Q33) -> 2757616.7 | R35: =MEDIAN(R26:R33) -> 2524802.5 | S35: =MEDIAN(S26:S33) -> 5245797.6
C36: Mean | F36: =AVERAGE(F26:F33) -> 45.554439 | G36: =AVERAGE(G26:G33) -> 214.28976 | H36: =AVERAGE(H26:H33) -> 193.00979 | I36: =AVERAGE(I26:I33) -> 415.53835 | K36: =AVERAGE(K26:K33) -> 488389.14 | L36: =AVERAGE(L26:L33) -> 2297400.5 | M36: =AVERAGE(M26:M33) -> 2069258 | N36: =AVERAGE(N26:N33) -> 4454986.7 | P36: =AVERAGE(P26:P33) -> 1087127.1 | Q36: =AVERAGE(Q26:Q33) -> 2896138.5 | R36: =AVERAGE(R26:R33) -> 2667996 | S36: =AVERAGE(S26:S33) -> 5053724.7
C37: High | F37: =MAX(F26:F33) -> 184.16499 | G37: =MAX(G26:G33) -> 483.26296 | H37: =MAX(H26:H33) -> 333.37732 | I37: =MAX(I26:I33) -> 823.84708 | K37: =MAX(K26:K33) -> 1974432.9 | L37: =MAX(L26:L33) -> 5181062.1 | M37: =MAX(M26:M33) -> 3574138.3 | N37: =MAX(N26:N33) -> 8832464.6 | P37: =MAX(P26:P33) -> 2573170.9 | Q37: =MAX(Q26:Q33) -> 5779800.1 | R37: =MAX(R26:R33) -> 4172876.3 | S37: =MAX(S26:S33) -> 9431202.6
E40: Football Field Scenario Analysis
E41: Bear Case | F41: =F29 -> 116.74016 | G41: =G29-F29 -> 95.310024 | H41: =G41+F41 -> 212.05019
E42: Bull Case | F42: =F28 -> 163.15539 | G42: =G28-F28 -> 128.4627 | H42: =G42+F42 -> 291.61809
E43: Base Case | F43: =F27 -> 184.16499 | G43: =G27-F27 -> 108.82943 | H43: =G43+F43 -> 292.99442

Sheet Actuals FS
D3: Historic Financial Statements
D4: Figures in USD millions, unless told otherwise
C8: As Reported Comprehensive Financial Statements
C10: 1. Balance sheet (B/S), as of year end | D10: 2024 | E10: =D10-1 -> 2023 | F10: =E10-1 -> 2022 | G10: =F10-1 -> 2021 | H10: =G10-1 -> 2020 | J10: NOTES:
C11: ASSETS
C12: Cash and cash equivalents | D12: 78779 | E12: 73387 | F12: 53888 | G12: 36220 | H12: 42122
C13: Marketable securities | D13: 22423 | E13: 13393 | F13: 16138 | G13: 59829 | H13: 42274
C14: Inventories | D14: 34214 | E14: 33318 | F14: 34405 | G14: 32640 | H14: 23795 | J14: Source: Company Information - Amazon Investor Relations
C15: Accounts receivable, net and other | D15: 55451 | E15: 52253 | F15: 42360 | G15: 32891 | H15: 24542
C16: Total current assets | D16: =SUM(D12:D15) -> 190867 | E16: =SUM(E12:E15) -> 172351 | F16: =SUM(F12:F15) -> 146791 | G16: =SUM(G12:G15) -> 161580 | H16: =SUM(H12:H15) -> 132733
C17: Property and equipment, net | D17: 252665 | E17: 204177 | F17: 186715 | G17: 160281 | H17: 113114
C18: Operating leases | D18: 76141 | E18: 72513 | F18: 66123 | G18: 56082 | H18: 37553
C19: Goodwill | D19: 23074 | E19: 22789 | F19: 20288 | G19: 15371 | H19: 15017
C20: Other assets | D20: 82147 | E20: 56024 | F20: 42758 | G20: 27235 | H20: 22778
C21: Total assets | D21: =SUM(D16,D17:D20) -> 624894 | E21: =SUM(E16,E17:E20) -> 527854 | F21: =SUM(F16,F17:F20) -> 462675 | G21: =SUM(G16,G17:G20) -> 420549 | H21: =SUM(H16,H17:H20) -> 321195
C23: LIABILITIES
C24: Accounts payable | D24: 94363 | E24: 84981 | F24: 79600 | G24: 78664 | H24: 72539
C25: Accrued expenses and other | D25: 66965 | E25: 64709 | F25: 62566 | G25: 51775 | H25: 44138
C26: Unearned revenue | D26: 18103 | E26: 15227 | F26: 13227 | G26: 11827 | H26: 9708
C27: Total current liabilities | D27: =SUM(D24:D26) -> 179431 | E27: =SUM(E24:E26) -> 164917 | F27: =SUM(F24:F26) -> 155393 | G27: =SUM(G24:G26) -> 142266 | H27: =SUM(H24:H26) -> 126385
C28: Long-term lease liabilities | D28: 78277 | E28: 77297 | F28: 72968 | G28: 67651 | H28: 52573
C29: Long-term debt | D29: 52623 | E29: 58314 | F29: 67150 | G29: 48744 | H29: 31816
C30: Other long-term liabilities | D30: 28593 | E30: 25451 | F30: 21121 | G30: 23643 | H30: 17017
C31: Commitments and contingencies (Note 7) | D31: 0 | E31: 0 | F31: 0 | G31: 0 | H31: 0
C32: Total liabilities | D32: =SUM(D27,D28:D31) -> 338924 | E32: =SUM(E27,E28:E31) -> 325979 | F32: =SUM(F27,F28:F31) -> 316632 | G32: =SUM(G27,G28:G31) -> 282304 | H32: =SUM(H27,H28:H31) -> 227791
C34: SHAREHOLDERS EQUITY
C35: Preferred stock ($0.01 par value; 500 shares authorized) | D35: 0 | E35: 0 | F35: 0 | G35: 0 | H35: 0
C36: Common stock ($0.01 par value; 100,000 shares authorized) | D36: 111 | E36: 109 | F36: 108 | G36: 106 | H36: 5
C37: Treasury stock, at cost | D37: -7837 | E37: -7837 | F37: -7837 | G37: -1837 | H37: -1837
C38: Additional paid-in capital | D38: 120864 | E38: 99025 | F38: 75066 | G38: 55437 | H38: 42865
C39: Accumulated other comprehensive income (loss) | D39: -34 | E39: -3040 | F39: -4487 | G39: -1376 | H39: -180
C40: Retained earnings | D40: 172866 | E40: 113618 | F40: 83193 | G40: 85915 | H40: 52551
C41: Total shareholders' equity | D41: =SUM(D35:D40) -> 285970 | E41: =SUM(E35:E40) -> 201875 | F41: =SUM(F35:F40) -> 146043 | G41: =SUM(G35:G40) -> 138245 | H41: =SUM(H35:H40) -> 93404
C42: Total liabilities & shareholders' equity | D42: =D41+D32 -> 624894 | E42: =E41+E32 -> 527854 | F42: =F41+F32 -> 462675 | G42: =G41+G32 -> 420549 | H42: =H41+H32 -> 321195
C44: 2. Income Statement for the year ended | D44: =D10 -> 2024 | E44: =E10 -> 2023 | F44: =F10 -> 2022 | G44: =G10 -> 2021 | H44: =H10 -> 2020
C45: Net product sales | D45: 272311 | E45: 255887 | F45: 242901 | G45: 241787 | H45: 215915
C46: Net service sales | D46: 365648 | E46: 318898 | F46: 271082 | G46: 228035 | H46: 170149
C47: Total net sales | D47: =SUM(D45:D46) -> 637959 | E47: =SUM(E45:E46) -> 574785 | F47: =SUM(F45:F46) -> 513983 | G47: =SUM(G45:G46) -> 469822 | H47: =SUM(H45:H46) -> 386064
C48: Cost of sales | D48: 326288 | E48: 304739 | F48: 288831 | G48: 272344 | H48: 233307
C49: Fulfillment | D49: 98505 | E49: 90619 | F49: 84299 | G49: 75111 | H49: 58517
...

Sheet HWMS Model
F2: AMZN Quarterly Sales Forecasting: Holt-Winters Multiplicative Seasonal (HWMS) Model
F3: Figures in USD millions, unless told otherwise
D7: Sensitivity Factors & Forecast Error
D8: Alpha | G8: 0.72757044
D9: Beta | G9: 0.19620896
D10: Gamma | G10: 1
D11: Mean Squared Error (MSE) | G11: =SUMXMY2(E20:E56,I20:I56)/COUNT(E20:E56) -> 19956348
D12: Mean Absolute % Error (MAPE) | G12: {=AVERAGE(ABS(E20:E56-I20:I56)/E20:E56)} -> 0.042656503
D14: Sales Forecasting
D15: Date | E15: Sales | F15: Level | G15: Trend | H15: Seasonal | I15: Forecast
C16: Actual | D16: 42277 | E16: 25358 | H16: =E16/$F$19 -> 0.8408034
D17: 42369 | E17: 35747 | H17: =E17/$F$19 -> 1.1852748
D18: 42460 | E18: 29128 | H18: =E18/$F$19 -> 0.96580651
D19: 42551 | E19: 30404 | F19: =AVERAGE(E16:E19) -> 30159.25 | G19: 0 | H19: =E19/$F$19 -> 1.0081153
D20: 42643 | E20: 32714 | F20: =$G$8*(E20/H16)+(1-$G$8)*(F19+G19) -> 36524.6 | G20: =$G$9*(F20-F19)+(1-$G$9)*G19 -> 1248.9387 | H20: =$G$10*(E20/F20)+(1-$G$10)*H16 -> 0.89567031 | I20: =SUM(F19:G19)*H16 -> 25358
D21: 42735 | E21: 43741 | F21: =$G$8*(E21/H17)+(1-$G$8)*(F20+G20) -> 37140.653 | G21: =$G$9*(F21-F20)+(1-$G$9)*G20 -> 1124.7609 | H21: =$G$10*(E21/F21)+(1-$G$10)*H17 -> 1.1777122 | I21: =SUM(F20:G20)*H17 -> 44772.025
D22: 42825 | E22: 35714 | F22: =$G$8*(E22/H18)+(1-$G$8)*(F21+G21) -> 37329.036 | G22: =$G$9*(F22-F21)+(1-$G$9)*G21 -> 941.03514 | H22: =$G$10*(E22/F22)+(1-$G$10)*H18 -> 0.95673512 | I22: =SUM(F21:G21)*H18 -> 36956.986
D23: 42916 | E23: 37955 | F23: =$G$8*(E23/H19)+(1-$G$8)*(F22+G22) -> 37818.537 | G23: =$G$9*(F23-F22)+(1-$G$9)*G22 -> 852.43996 | H23: =$G$10*(E23/F23)+(1-$G$10)*H19 -> 1.0036084 | I23: =SUM(F22:G22)*H19 -> 38580.643
D24: 43008 | E24: 43744 | F24: =$G$8*(E24/H20)+(1-$G$8)*(F23+G23) -> 46069.22 | G24: =$G$9*(F24-F23)+(1-$G$9)*G23 -> 2304.0417 | H24: =$G$10*(E24/F24)+(1-$G$10)*H20 -> 0.94952768 | I24: =SUM(F23:G23)*H20 -> 34636.445
D25: 43100 | E25: 60453 | F25: =$G$8*(E25/H21)+(1-$G$8)*(F24+G24) -> 50525.136 | G25: =$G$9*(F25-F24)+(1-$G$9)*G24 -> 2726.2586 | H25: =$G$10*(E25/F25)+(1-$G$10)*H21 -> 1.1964936 | I25: =SUM(F24:G24)*H21 -> 56969.78
D26: 43190 | E26: 51042 | F26: =$G$8*(E26/H22)+(1-$G$8)*(F25+G25) -> 53323.275 | G26: =$G$9*(F26-F25)+(1-$G$9)*G25 -> 2740.3621 | H26: =$G$10*(E26/F26)+(1-$G$10)*H22 -> 0.95721803 | I26: =SUM(F25:G25)*H22 -> 50947.479
D27: 43281 | E27: 52886 | F27: =$G$8*(E27/H23)+(1-$G$8)*(F26+G26) -> 53613.337 | G27: =$G$9*(F27-F26)+(1-$G$9)*G26 -> 2259.5914 | H27: =$G$10*(E27/F27)+(1-$G$10)*H23 -> 0.98643365 | I27: =SUM(F26:G26)*H23 -> 56265.936
D28: 43373 | E28: 56576 | F28: =$G$8*(E28/H24)+(1-$G$8)*(F27+G27) -> 58572.491 | G28: =$G$9*(F28-F27)+(1-$G$9)*G27 -> 2789.2697 | H28: =$G$10*(E28/F28)+(1-$G$10)*H24 -> 0.96591419 | I28: =SUM(F27:G27)*H24 -> 53052.892
D29: 43465 | E29: 72383 | F29: =$G$8*(E29/H25)+(1-$G$8)*(F28+G28) -> 60731.813 | G29: =$G$9*(F29-F28)+(1-$G$9)*G28 -> 2665.6684 | H29: =$G$10*(E29/F29)+(1-$G$10)*H25 -> 1.1918465 | I29: =SUM(F28:G28)*H25 -> 73418.952
D30: 43555 | E30: 59700 | F30: =$G$8*(E30/H26)+(1-$G$8)*(F29+G29) -> 62648.633 | G30: =$G$9*(F30-F29)+(1-$G$9)*G29 -> 2518.7376 | H30: =$G$10*(E30/F30)+(1-$G$10)*H26 -> 0.9529338 | I30: =SUM(F29:G29)*H26 -> 60685.212
D31: 43646 | E31: 63404 | F31: =$G$8*(E31/H27)+(1-$G$8)*(F30+G30) -> 64518.829 | G31: =$G$9*(F31-F30)+(1-$G$9)*G30 -> 2391.4879 | H31: =$G$10*(E31/F31)+(1-$G$10)*H27 -> 0.98272088 | I31: =SUM(F30:G30)*H27 -> 64283.287
... D56: 45930 | E56: 180169 | F56: =$G$8*(E56/H52)+(1-$G$8)*(F55+G55) -> 176956.24 | G56: =$G$9*(F56-F55)+(1-$G$9)*G55 -> 4887.8339 | H56: =$G$10*(E56/F56)+(1-$G$10)*H52 -> 1.0181557 | I56: =SUM(F55:G55)*H52 -> 174112.53
C57: Forecast | D57: 46022 | I57: =($F$56+$G$56*(ROW()-ROW($I$56)))*H52 -> 183450.04
D58: 46112 | I58: =($F$56+$G$56*(ROW()-ROW($I$56)))*H53 -> 217630.42
D59: 46203 | I59: =($F$56+$G$56*(ROW()-ROW($I$56)))*H54 -> 184178.6
D60: 46295 | I60: =($F$56+$G$56*(ROW()-ROW($I$56)))*H56 -> 200075.3
D61: FY 2025 | I61: =SUM(I57:I60) -> 785334.36
D63: 2023 | E63: =E77 -> 1128.9975
D64: 2029 | E64: =E76 -> 1026.3613
D65: 2028 | E65: =E75 -> 933.05575
D66: 2027 | E66: =E74 -> 856.01445
D67: 26 Q3 | E67: =I60/1000 -> 200.0753
D68: 26 Q2 | E68: =I59/1000 -> 184.1786
D69: 26 Q1 | E69: =I58/1000 -> 217.63042
D70: 25 Q4 | E70: =I57/1000 -> 183.45004
...

Sheet Revenue
D2: Revenue Breakdown & Projections
D3: Figures in USD millions, unless told otherwise
C30: Scenario Forecasted Revenues | O30: NOTES & SOURCES:
C32: In $ billions | D32: 2020 | E32: =D32+1 -> 2021 | F32: =E32+1 -> 2022 | G32: =F32+1 -> 2023 | H32: =G32+1 -> 2024 | I32: =H32+1 -> 2025 | J32: =I32+1 -> 2026 | K32: =J32+1 -> 2027 | L32: =K32+1 -> 2028 | M32: =L32+1 -> 2029 | O32: 5yr CAGR
C33: Base Case Revenues | D33: =(D52)/1000 -> 386.064 | E33: =(E52)/1000 -> 469.822 | F33: =(F52)/1000 -> 513.983 | G33: =(G52)/1000 -> 574.785 | H33: =(H52)/1000 -> 637.959 | I33: ='HWMS Model'!I61/1000 -> 785.33436 | J33: =I33*(1+J34) -> 856.01445 | K33: =J33*(1+K34) -> 933.05575 | L33: =K33*(1+L34) -> 1026.3613 | M33: =L33*(1+M34) -> 1128.9975 | O33: =RATE(5,,H33,-M33) -> 0.12093399
C34: Growth Rate (%) | E34: =E33/D33-1 -> 0.21695367 | F34: =F33/E33-1 -> 0.093995173 | G34: =G33/F33-1 -> 0.11829574 | H34: =H33/G33-1 -> 0.10990892 | I34: =I33/H33-1 -> 0.23101071 | J34: =Scenarios!F18 -> 0.09 | K34: =Scenarios!G18 -> 0.09 | L34: =Scenarios!H18 -> 0.1 | M34: =Scenarios!I18 -> 0.1
C35: Bull Case Revenues | D35: =D33 -> 386.064 | E35: =E33 -> 469.822 | F35: =F33 -> 513.983 | G35: =G33 -> 574.785 | H35: =H33 -> 637.959 | I35: =I33*(1+Scenarios!E19) -> 871.72114 | J35: =I35*(1+J36) -> 993.7621 | K35: =J35*(1+K36) -> 1132.8888 | L35: =K35*(1+L36) -> 1280.1643 | M35: =L35*(1+M36) -> 1446.5857 | O35: =RATE(5,,H35,-M35) -> 0.17790504
C36: Growth Rate (%) | E36: =E35/D35-1 -> 0.21695367 | F36: =F35/E35-1 -> 0.093995173 | G36: =G35/F35-1 -> 0.11829574 | H36: =H35/G35-1 -> 0.10990892 | I36: =I35/H35-1 -> 0.36642188 | J36: =Scenarios!F19 -> 0.14 | K36: =Scenarios!G19 -> 0.14 | L36: =Scenarios!H19 -> 0.13 | M36: =Scenarios!I19 -> 0.13
C37: Bear Case Revenues | D37: =D35 -> 386.064 | E37: =E35 -> 469.822 | F37: =F35 -> 513.983 | G37: =G35 -> 574.785 | H37: =H35 -> 637.959 | I37: =I33*(1+Scenarios!E20) -> 824.60108 | J37: =I37*(1+J38) -> 874.07714 | K37: =J37*(1+K38) -> 926.52177 | L37: =K37*(1+L38) -> 991.37829 | M37: =L37*(1+M38) -> 1060.7748 | O37: =RATE(5,,H37,-M37) -> 0.10704706
C38: Growth Rate (%) | E38: =E37/D37-1 -> 0.21695367 | F38: =F37/E37-1 -> 0.093995173 | G38: =G37/F37-1 -> 0.11829574 | H38: =H37/G37-1 -> 0.10990892 | I38: =I37/H37-1 -> 0.29256124 | J38: =Scenarios!F20 -> 0.06 | K38: =Scenarios!G20 -> 0.06 | L38: =Scenarios!H20 -> 0.07 | M38: =Scenarios!I20 -> 0.07
C40: AWS Remaining Performance Obligations (RPO)
C42: In $ billions | D42: 2020 | E42: =D42+1 -> 2021 | F42: =E42+1 -> 2022 | G42: =F42+1 -> 2023 | H42: =G42+1 -> 2024 | J42: 18 - 22 CAGR | L42: 19 - 22 CAGR
C43: AWS RPO (Backlog) | D43: 50000 | E43: 80000 | F43: 110400 | G43: 155700 | H43: 177000 | J43: =RATE(5,,D43,-H43) -> 0.28765836 | L43: =RATE(4,,E43,-H43) -> 0.21960956 | O43: Source: Company Information
C44: Growth Rate (%) | F44: =F43/E43-1 -> 0.38 | G44: =G43/F43-1 -> 0.41032609 | H44: =H43/G43-1 -> 0.13680154
E45: =E43/D43-1 -> 0.6
C46: Revenues by Business Segment, Forecasted with Industry Expectations
D48: 2020 | E48: =D48+1 -> 2021 | F48: =E48+1 -> 2022 | G48: =F48+1 -> 2023 | H48: =G48+1 -> 2024 | I48: =H48+1 -> 2025 | J48: =I48+1 -> 2026 | K48: =J48+1 -> 2027 | L48: =K48+1 -> 2028 | M48: =L48+1 -> 2029
C49: North America | D49: 236282 | E49: 279833 | F49: 315880 | G49: 352828 | H49: 387497 | I49: =H49*(1+I65) -> 395467.07 | J49: =I49*(1+J65) -> 403221.32 | K49: =J49*(1+K65) -> 410739.68 | L49: =K49*(1+L65) -> 418002.27 | M49: =L49*(1+M65) -> 425393.27 | O49: Following US government infrastructure spending, adjusted to gradual increase in market share
C50: International | D50: 104412 | E50: 127787 | F50: 118007 | G50: 131200 | H50: 142906 | I50: =H50*(1+I67) -> 150480.02 | J50: =I50*(1+J67) -> 158154.5 | K50: =J50*(1+K67) -> 166062.22 | L50: =K50*(1+L67) -> 174697.46 | M50: =L50*(1+M67) -> 183607.03 | O50: Following demand for critical minerals
C51: AWS | D51: 45370 | E51: 62202 | F51: 80096 | G51: 90757 | H51: 107556 | I51: =H51*(1+I69) -> 116707.61 | J51: =I51*(1+J69) -> 127124.13 | K51: =J51*(1+K69) -> 135993.26 | L51: =K51*(1+L69) -> 146066.83 | M51: =L51*(1+M69) -> 155622.61 | O51: Following demand for engine turbine manufacturing in the US, adjusted to gradual increase in market share
C52: Total Revenues | D52: =SUM(D49:D51) -> 386064 | E52: =SUM(E49:E51) -> 469822 | F52: =SUM(F49:F51) -> 513983 | G52: =SUM(G49:G51) -> 574785 | H52: =SUM(H49:H51) -> 637959 | I52: =SUM(I49:I51) -> 662654.69 | J52: =SUM(J49:J51) -> 688499.96 | K52: =SUM(K49:K51) -> 712795.16 | ... M52: =SUM(M49:M51) -> 764622.91
C53: Growth Rate (%) | E53: =E52/D52-1 -> 0.21695367 | F53: =F52/E52-1 -> 0.093995173 | G53: =G52/F52-1 -> 0.11829574 | H53: =H52/G52-1 -> 0.10990892 | I53: =I52/H52-1 -> 0.038710469 | J53: =J52/I52-1 -> 0.039002611 | K53: =K52/J52-1 -> 0.035287158 | L53: =L52/K52-1 -> 0.036435991 | M53: =M52/L52-1 -> 0.034999347
C55: As % of Total | D55: 2020 | E55: =D55+1 -> 2021 | F55: =E55+1 -> 2022 | G55: =F55+1 -> 2023 | H55: =G55+1 -> 2024 | I55: =H55+1 -> 2025 | J55: =I55+1 -> 2026 | K55: =J55+1 -> 2027 | L55: =K55+1 -> 2028 | M55: =L55+1 -> 2029
C56: North America | D56: =D49/(D$52) -> 0.61202806 | E56: =E49/(E$52) -> 0.59561494 | F56: =F49/(F$52) -> 0.61457286 | G56: =G49/(G$52) -> 0.61384344 | H56: =H49/(H$52) -> 0.6074011 | I56: =I49/(I$52) -> 0.59679207 | J56: =J49/(J$52) -> 0.58565192 | K56: =K49/(K$52) -> 0.57623803 | ... M56: =M49/(M$52) -> 0.55634387
C57: International | D57: =D50/(D$52) -> 0.27045257 | E57: =E50/(E$52) -> 0.27199024 | F57: =F50/(F$52) -> 0.2295932 | G57: =G50/(G$52) -> 0.22825926 | H57: =H50/(H$52) -> 0.22400499 | I57: =I50/(I$52) -> 0.22708663 | J57: =J50/(J$52) -> 0.2297088 | K57: =K50/(K$52) -> 0.23297328 | ... M57: =M50/(M$52) -> 0.24012756
C58: AWS | D58: =D51/(D$52) -> 0.11751938 | E58: =E51/(E$52) -> 0.13239482 | F58: =F51/(F$52) -> 0.15583395 | G58: =G51/(G$52) -> 0.1578973 | H58: =H51/(H$52) -> 0.16859391 | I58: =I51/(I$52) -> 0.1761213 | J58: =J51/(J$52) -> 0.18463928 | K58: =K51/(K$52) -> 0.1907887 | ... M58: =M51/(M$52) -> 0.20352857
C59: Total Revenues | D59: =SUM(D56:D58) -> 1 | E59: =SUM(E56:E58) -> 1 | F59: =SUM(F56:F58) -> 1 | G59: =SUM(G56:G58) -> 1 | H59: =SUM(H56:H58) -> 1 | I59: =SUM(I56:I58) -> 1 | J59: =SUM(J56:J58) -> 1 | K59: =SUM(K56:K58) -> 1 | ... M59: =SUM(M56:M58) -> 1
C61: Economic Indicators
D63: 2020 | E63: =D63+1 -> 2021 | F63: =E63+1 -> 2022 | G63: =F63+1 -> 2023 | H63: =G63+1 -> 2024 | I63: =H63+1 -> 2025 | J63: =I63+1 -> 2026 | K63: =J63+1 -> 2027 | L63: =K63+1 -> 2028 | M63: =L63+1 -> 2029
C64: Real PCE (NA Driver) | D64: 13597 | E64: 14792 | F64: 15237 | G64: 15628 | H64: 16089 | I64: =H64*(1+2.1%) -> 16426.869 | J64: =I64*(1+2%) -> 16755.406 | K64: =J64*(1+1.9%) -> 17073.759 | L64: =K64*(1+1.8%) -> 17381.087 | M64: =L64*(1+1.8%) -> 17693.946 | O64: The Congressional Budget Office (CBO) and Federal Reserve consensus forecast US real GDP and consumption to settle at a long-run trend of 1.8% for the 2027–2031 period.
C65: PCE Growth Rate | E65: =1-D64/E64 -> 0.080786912 | F65: =1-E64/F64 -> 0.029205224 | G65: =1-F64/G64 -> 0.025019196 | H65: =1-G64/H64 -> 0.028653117 | I65: =1-H64/I64 -> 0.020568071 | J65: =1-I64/J64 -> 0.019607843 | K65: =1-J64/K64 -> 0.018645731 | L65: =1-K64/L64 -> 0.017681729 | M65: =1-L64/M64 -> 0.017681729 | O65: Source: CBO/BEA
C66: Global GDP (Int Driver) | D66: 85200 | E66: 96500 | F66: 100500 | G66: 104800 | H66: 111300 | I66: =H66*(1+5.3%) -> 117198.9 | J66: =I66*(1+5.1%) -> 123176.04 | K66: =J66*(1+5%) -> 129334.85 | L66: =K66*(1+5.2%) -> 136060.26 | M66: =L66*(1+5.1%) -> 142999.33 | O66: The global economy saw a sharp nominal increase in 2021 as activities resumed and inflation rose. From 2024 onwards, growth is expected to stabilize around 5-6% annually, driven by a real GDP growth of approximately 3.2% and moderating inflation. By 2028, the global economy is projected to surpass $136 trillion, reflecting continued expansion in emerging markets and steady growth in advanced economies like the U.S. and China.
C67: Growth in GDP | E67: =E66/D66-1 -> 0.13262911 | F67: =F66/E66-1 -> 0.041450777 | G67: =G66/F66-1 -> 0.04278607 | H67: =H66/G66-1 -> 0.062022901 | I67: =I66/H66-1 -> 0.053 | J67: =J66/I66-1 -> 0.051 | K67: =K66/J66-1 -> 0.05 | L67: =L66/K66-1 -> 0.052 | M67: =M66/L66-1 -> 0.051 | O67: Source: CBO/IMF
C68: Global IT Spending (AWS Driver) | D68: 3695 | E68: 4241 | F68: 4533 | G68: 4693 | H68: 5069 | I68: =H68*(1+9.3%) -> 5540.417 | J68: =I68*(1+9.8%) -> 6083.3779 | K68: =J68*(1+7.5%) -> 6539.6312 | L68: =K68*(1+8%) -> 7062.8017 | M68: =L68*(1+7%) -> 7557.1978 | O68: Global IT spending is forecast to accelerate primarily due to a surge in investment for data center systems and servers to support Generative AI infrastructure, alongside continued double-digit growth in software and IT services as enterprises integrate these technologies.
C69: Growth in IT Spending | E69: =1-D68/E68 -> 0.12874322 | F69: =1-E68/F68 -> 0.064416501 | G69: =1-F68/G68 -> 0.03409333 | H69: =1-G68/H68 -> 0.074176366 | I69: =1-H68/I68 -> 0.085086917 | J69: =1-I68/J68 -> 0.089253188 | K69: =1-J68/K68 -> 0.069767442 | L69: =1-K68/L68 -> 0.074074074 | M69: =1-L68/M68 -> 0.065420561 | O69: Source: Gartner
C71: Revenues by Geographic Presence, Forecasted with Regional GDP Expectations
D73: 2020 | E73: =D73+1 -> 2021 | F73: =E73+1 -> 2022 | G73: =F73+1 -> 2023 | H73: =G73+1 -> 2024 | I73: =H73+1 -> 2025 | J73: =I73+1 -> 2026 | K73: =J73+1 -> 2027 | L73: =K73+1 -> 2028 | M73: =L73+1 -> 2029
C74: United States | D74: 263520 | E74: 314006 | F74: 356113 | G74: 395637 | H74: 438015 | I74: =H74*(1+I93) -> 447651.33 | J74: =I74*(1+J93) -> 457052.01 | K74: =J74*(1+K93) -> 465736 | L74: =K74*(1+L93) -> 474119.24 | M74: =L74*(1+M93) -> 482653.39
C75: Germany | D75: 29565 | E75: 31645 | F75: 33598 | G75: 37588 | H75: 40856 | I75: =H75*(1+I94) -> 41182.848 | J75: =I75*(1+J94) -> 41677.042 | K75: =J75*(1+K94) -> 42260.521 | L75: =K75*(1+L94) -> 42809.908 | M75: =L75*(1+M94) -> 43366.436
C76: United Kingdom | D76: 26483 | E76: 27907 | F76: 30074 | G76: 33591 | H76: 37855 | I76: =H76*(1+I95) -> 38422.825 | J76: =I76*(1+J95) -> 38922.322 | K76: =J76*(1+K95) -> 39467.234 | L76: =K76*(1+L95) -> 40059.243 | M76: =L76*(1+M95) -> 40660.131
...

Sheet Scenarios
C3: Scenario Assumptions
C4: Figures in USD millions, unless told otherwise
C8: Case Scenario | D8: 1
C9: Base Case | D9: 1
C10: Bull | D10: 2
C11: Bear | D11: 3
C13: Scenario Assumption Table | K13: NOTE: Base case assumptions are carried forward in the bear and bull cases, unless told otherwise
D15: 5yr Avg. | E15: 2025 | F15: 2026 | G15: 2027 | H15: 2028 | I15: 2029 | K15: Main Rationale
C17: Sales Growth (%) | D17: =AVERAGE('Actuals FS'!D149:G149) -> 0.13478838 | E17: =CHOOSE($D$8,E18,E19,E20) -> 0.07 | F17: =CHOOSE($D$8,F18,F19,F20) -> 0.09 | G17: =CHOOSE($D$8,G18,G19,G20) -> 0.09 | H17: =CHOOSE($D$8,H18,H19,H20) -> 0.1 | I17: =CHOOSE($D$8,I18,I19,I20) -> 0.1
C18: Base Case | E18: 0.07 | F18: 0.09 | G18: 0.09 | H18: 0.1 | I18: 0.1 | K18: The most recent company guidance is for Q1 2025 Net Sales to be between 5% and 9% growth. We adopt the midpoint of the range (7.0%) for 2025, then project a steady increase toward 10.0% by 2028-2029, assuming successful realization of investments.
C19: Bull | E19: =E18+4% -> 0.11 | F19: 0.14 | G19: 0.14 | H19: 0.13 | I19: 0.13 | K19: This scenario reflects high-end analyst expectations based on the AWS re-acceleration (which was the highest-growth segment at 19% in 2024). It assumes the AI infrastructure investments and the strong advertising segment drive growth well above the immediate guidance.
C20: Bear | E20: 0.05 | F20: 0.06 | G20: 0.06 | H20: 0.07 | I20: 0.07 | K20: This uses the low end of the Q1 2025 guidance (5%) and anticipates slower-than-expected recovery in the International segment (which grew 9% in 2024) and poor performance in the highly competitive North America segment.
C21: Cost of Sales (% of sales) | D21: =AVERAGE('Actuals FS'!D150:H150) -> 0.48001736 | E21: =CHOOSE($D$8,E22,E23,E24) -> 0.51 | F21: =CHOOSE($D$8,F22,F23,F24) -> 0.505 | G21: =CHOOSE($D$8,G22,G23,G24) -> 0.5 | H21: =CHOOSE($D$8,H22,H23,H24) -> 0.495 | I21: =CHOOSE($D$8,I22,I23,I24) -> 0.49
C22: Base Case | E22: 0.51 | F22: 0.505 | G22: 0.5 | H22: 0.495 | I22: 0.49 | K22: Starts at 51.0% (aligning with the 2024 actuals) and improves to 49.0%, assuming efficiencies take time to materialize.
C23: Bull | E23: 0.505 | F23: 0.49 | G23: 0.48 | H23: 0.47 | I23: 0.46 | K23: Drops aggressively to 46.0% (surpassing your 48% historical average) due to rapid growth in high-margin AWS/Advertising revenue which dilutes the cost of retail goods.
C24: Bear | E24: 0.515 | F24: 0.52 | G24: 0.525 | H24: 0.53 | I24: 0.535 | K24: Rises to 53.5%, reflecting risks of inventory markdowns and inflation cited in the 10-K.
C25: Fulfillment Expense (% of sales) | D25: =AVERAGE('Actuals FS'!D161:H161) -> 0.15750389 | E25: =CHOOSE($D$8,E26,E27,E28) -> 0.154 | F25: =CHOOSE($D$8,F26,F27,F28) -> 0.152 | G25: =CHOOSE($D$8,G26,G27,G28) -> 0.15 | H25: =CHOOSE($D$8,H26,H27,H28) -> 0.148 | I25: =CHOOSE($D$8,I26,I27,I28) -> 0.146
C26: Base Case | E26: 0.154 | F26: 0.152 | G26: 0.15 | H26: 0.148 | I26: 0.146 | K26: Slight improvement from 2024 (15.4%) to 14.6%. Rationale: Continued realization of "regionalization" efficiencies in the logistics network, which reduces miles driven and cost per package.
C27: Bull | E27: 0.15 | F27: 0.145 | G27: 0.14 | H27: 0.135 | I27: 0.13 | K27: Aggressive drop to 13.0%. Rationale: Robotics and automation in fulfillment centers significantly lower labor intensity, addressing the "constrained labor market" risk by reducing reliance on temporary staffing.
C28: Bear | E28: 0.16 | F28: 0.165 | G28: 0.165 | H28: 0.17 | I28: 0.17 | K28: Increases to 17.0%. Rationale: Labor shortages force wage hikes, and "variability in demand" leads to underutilized capacity in the massive logistics footprint, driving up fixed costs per unit.
C29: Tech & Infra (% of sales) | D29: =AVERAGE('Actuals FS'!D154:H154) -> 0.13204208 | E29: =CHOOSE($D$8,E30,E31,E32) -> -0.145 | F29: =CHOOSE($D$8,F30,F31,F32) -> -0.145 | G29: =CHOOSE($D$8,G30,G31,G32) -> -0.14 | H29: =CHOOSE($D$8,H30,H31,H32) -> -0.135 | I29: =CHOOSE($D$8,I30,I31,I32) -> -0.13
C30: Base Case | E30: -0.145 | F30: -0.145 | G30: -0.14 | H30: -0.135 | I30: -0.13 | K30: Assumes the ratio initially worsens to -14.5% due to expected increases in AI infrastructure spending, then improves as those investments mature and revenue leverage kicks in.
C31: Bull | E31: -0.135 | F31: -0.13 | G31: -0.125 | H31: -0.12 | I31: -0.115 | K31: Models a rapid improvement to -11.5% as high-margin AWS revenue grows faster than the fixed costs of the new data centers.
C32: Bear | E32: -0.15 | F32: -0.155 | G32: -0.16 | H32: -0.16 | I32: -0.16 | K32: Reflects a deterioration to -16.0% driven by "service disruptions" or low utilization of the expanded infrastructure, causing costs to outpace sales growth.
C33: S&M + G&A (% of sales) | D33: =AVERAGE('Actuals FS'!D153:H153) -> 0.37995287 | E33: =CHOOSE($D$8,E34,E35,E36) -> 0.087 | F33: =CHOOSE($D$8,F34,F35,F36) -> 0.086 | G33: =CHOOSE($D$8,G34,G35,G36) -> 0.085 | H33: =CHOOSE($D$8,H34,H35,H36) -> 0.084 | I33: =CHOOSE($D$8,I34,I35,I36) -> 0.083
C34: Base Case | E34: 0.087 | F34: =E34-0.1% -> 0.086 | G34: =F34-0.1% -> 0.085 | H34: =G34-0.1% -> 0.084 | I34: =H34-0.1% -> 0.083 | K34: Assumes a gradual improvement from the 2024 level as the company continues to realize efficiencies in payroll and maintains a lean corporate structure to let revenue grow faster than overhead.
C35: Bull | E35: 0.085 | F35: =E35-0.5% -> 0.08 | G35: =F35-0.5% -> 0.075 | H35: =G35-0.5% -> 0.07 | I35: =H35-0.5% -> 0.065 | K35: Models significant operating leverage where rapid growth in high-margin AWS and advertising revenue requires far less incremental marketing spend per dollar earned compared to retail.
C36: Bear | E36: 0.09 | F36: =E36+0.5% -> 0.095 | G36: =F36 -> 0.095 | H36: =G36+0.5% -> 0.1 | I36: =H36 -> 0.1 | K36: Reflects rising costs due to "intense competition" for advertising traffic driving up marketing rates and "constrained labor markets" forcing higher wages for corporate staff.
C37: Effective Tax Rate (%) | D37: =AVERAGE('Actuals FS'!D159:H159) -> -0.22211001 | E37: =CHOOSE($D$8,E38,E39,E40) -> -0.15 | F37: =CHOOSE($D$8,F38,F39,F40) -> -0.16 | G37: =CHOOSE($D$8,G38,G39,G40) -> -0.17 | H37: =CHOOSE($D$8,H38,H39,H40) -> -0.17 | I37: =CHOOSE($D$8,I38,I39,I40) -> -0.17
C38: Base Case | E38: -0.15 | F38: =E38-1% -> -0.16 | G38: =F38-1% -> -0.17 | H38: =G38 -> -0.17 | I38: =H38 -> -0.17 | K38: Assumes the rate normalizes from the 2024 low (-13.5%) to -17.0% as new global minimum tax rules (Pillar Two) take effect and U.S. deductions phase out.
C39: Bull | E39: -0.12 | F39: =E39-0.5% -> -0.125 | G39: =F39-0.5% -> -0.13 | H39: =G39-0.5% -> -0.135 | I39: =H39-0.5% -> -0.14 | K39: Models a lower effective rate (-12.0% to -14.0%) driven by the successful maximization of R&D tax credits and "Foreign-Derived Intangible Income" deductions.
C40: Bear | E40: -0.18 | F40: =E40-1% -> -0.19 | G40: =F40-1% -> -0.2 | H40: =G40-1% -> -0.21 | I40: =H40 -> -0.21 | K40: Reflects a surge in tax expense to -21.0% due to adverse outcomes in ongoing "tax controversies" (such as the Indian tax authority dispute) and stricter international enforcement.
C41: Implied EBITDA Margin (%) | D41: =AVERAGE('Actuals FS'!D157:H157) -> 0.11879461 | E41: =1-SUM(E21,E25,E29,E37,E17,E33) -> 0.474 | F41: =1-SUM(F21,F25,F29,F37,F17,F33) -> 0.472 | G41: =1-SUM(G21,G25,G29,G37,G17,G33) -> 0.485 | H41: =1-SUM(H21,H25,H29,H37,H17,H33) -> 0.478 | I41: =1-SUM(I21,I25,I29,I37,I17,I33) -> 0.481
C43: Days in Receivables | D43: =AVERAGE('Actuals FS'!D113:H113) -> 28.748894 | E43: =CHOOSE($D$8,E44,E45,E46) -> 29 | F43: =CHOOSE($D$8,F44,F45,F46) -> 29 | G43: =CHOOSE($D$8,G44,G45,G46) -> 29 | H43: =CHOOSE($D$8,H44,H45,H46) -> 29 | I43: =CHOOSE($D$8,I44,I45,I46) -> 29
C44: Base Case | E44: 29 | F44: 29 | G44: 29 | H44: 29 | I44: 29 | K44: Maintains stability at 29 days, reflecting the high proportion of consumer sales settled instantly via credit card which keeps the collection cycle short.
C45: Bull | E45: 28 | F45: =E45 -> 28 | G45: =F45-0.5 -> 27.5 | H45: =G45 -> 27.5 | I45: =H45-0.5 -> 27 | K45: Drops to 27.0 days as the revenue mix shifts toward high-velocity digital services (AWS and Advertising) which settle faster than physical retail invoicing.
C46: Bear | E46: 30 | F46: =E46+1 -> 31 | G46: =F46+1 -> 32 | H46: =G46 -> 32 | I46: =H46+1 -> 33 | K46: Increases to 33.0 days due to "global economic conditions" causing slower payments from enterprise AWS customers and extended credit terms to stimulate retail sales.
C47: Days in Inventory | D47: =AVERAGE('Actuals FS'!D116:H116) -> 40.525789 | E47: =CHOOSE($D$8,E48,E49,E50) -> 40 | F47: =CHOOSE($D$8,F48,F49,F50) -> 39 | G47: =CHOOSE($D$8,G48,G49,G50) -> 38 | H47: =CHOOSE($D$8,H48,H49,H50) -> 37 | I47: =CHOOSE($D$8,I48,I49,I50) -> 36
C48: Base Case | E48: 40 | F48: =E48-1 -> 39 | G48: =F48-1 -> 38 | H48: =G48-1 -> 37 | I48: =H48-1 -> 36 | K48: Assumes a gradual improvement from 40.5 to 36 days as "fulfillment network efficiencies" and regionalization initiatives allow for faster turnover of stock.
C49: Bull | E49: 38 | F49: =E49-2 -> 36 | G49: =F49-2 -> 34 | H49: =G49-2 -> 32 | I49: =H49-2 -> 30 | K49: Improves significantly to 30.0 days driven by "regionalization" and predictive AI significantly reducing the need for safety stock across the fulfillment network.
...

Sheet Multiples
C3: Relative Multiples Valuation Model Based on Selected Industry Peers
C4: Figures in USD millions, unless told otherwise
C8: AMZN Intrinsic Value Based on Selected Comparable Companies
E10: EV/Sales | F10: EV/EBIT | G10: EV/EBITDA | H10: P/E
C11: Selected Multiple | E11: =R39 -> 9.0598301 | F11: =S39 -> 28.84199 | G11: =T39 -> 21.096831 | H11: =U39 -> 34.505254
C12: Operating Metric | E12: ='Forecasted FS'!E37 -> 637959 | F12: ='Forecasted FS'!E47 -> 68593 | G12: ='Forecasted FS'!E47 -> 68593 | H12: ='Forecasted FS'!E56 -> 59248
C13: Enterprise Value | E13: =E12*E11 -> 5779800.1 | F13: =F12*F11 -> 1978358.6 | G13: =G12*G11 -> 1447094.9 | H13: =H17-SUM(H14:H16) -> 2643105.3
C14: - Debt | E14: =DCF!$I$44 -> -52623 | F14: =DCF!$I$44 -> -52623 | G14: =DCF!$I$44 -> -52623 | H14: =DCF!$I$44 -> -52623
C15: + Cash | E15: =DCF!$I$45 -> 78779 | F15: =DCF!$I$45 -> 78779 | G15: =DCF!$I$45 -> 78779 | H15: =DCF!$I$45 -> 78779
C16: - Minority Interest | E16: =DCF!$I$46 -> -624894 | F16: =DCF!$I$46 -> -624894 | G16: =DCF!$I$46 -> -624894 | H16: =DCF!$I$46 -> -624894
C17: Equity Value | E17: =SUM(E13:E16) -> 5181062.1 | F17: =SUM(F13:F16) -> 1379620.6 | G17: =SUM(G13:G16) -> 848356.9 | H17: =H11*H12 -> 2044367.3
C18: Shares Outstanding | E18: =DCF!$E$15 -> 10721 | F18: =DCF!$E$15 -> 10721 | G18: =DCF!$E$15 -> 10721 | H18: =DCF!$E$15 -> 10721
C20: Implied Price | E20: =E17/E18 -> 483.26296 | F20: =F17/F18 -> 128.68395 | G20: =G17/G18 -> 79.130389 | H20: =H17/H18 -> 190.68812
C22: NOTE: Median value of comparable companies table to eliminate outliers
C24: Relative Valuation Summary
F26: Company Information | I26: Market Data | M26: Financial Data | R26: Valuation
D27: Company Name | F27: Ticker | G27: Country | I27: Price ($/share) | J27: Market Cap | K27: EV | M27: Sales | N27: EBIT | O27: EBITDA | P27: Earnings | R27: EV/Sales | S27: EV/EBIT | T27: EV/EBITDA | U27: P/E
C28: 1 | D28: Microsoft Corporation | F28: =VLOOKUP($D28,'Peer Fin Info'!$D$11:$R$20,2,FALSE) -> MSFT | G28: =VLOOKUP($D28,'Peer Fin Info'!$D$11:$R$20,3,FALSE) -> USA | I28: =VLOOKUP(F28,'Peer Mkt Info'!$E$10:$M$19,9,FALSE) -> 483.47 | J28: =VLOOKUP($D28,'Peer Fin Info'!$D$11:$R$20,14,FALSE) -> 3556616 | K28: =VLOOKUP($D28,'Peer Fin Info'!$D$11:$R$20,15,FALSE) -> 3515167 | M28: =VLOOKUP($D28,'Peer Fin Info'!$D$11:$R$20,5,FALSE) -> 293812 | N28: =VLOOKUP($D28,'Peer Fin Info'!$D$11:$R$20,6,FALSE) -> 127218 | O28: =VLOOKUP($D28,'Peer Fin Info'!$D$11:$R$20,7,FALSE) -> 167049 | P28: =VLOOKUP($D28,'Peer Fin Info'!$D$11:$R$20,8,FALSE) -> 104912 | R28: =$K28/M28 -> 11.964001 | S28: =$K28/N28 -> 27.631051 | T28: =$K28/O28 -> 21.04273 | U28: =J28/P28 -> 33.900946
C29: =C28+1 -> 2 | D29: Alphabet Inc. | F29: =VLOOKUP($D29,'Peer Fin Info'!$D$11:$R$20,2,FALSE) -> GOOGL | G29: =VLOOKUP($D29,'Peer Fin Info'!$D$11:$R$20,3,FALSE) -> USA | I29: =VLOOKUP(F29,'Peer Mkt Info'!$E$10:$M$19,9,FALSE) -> 312.43 | J29: =VLOOKUP($D29,'Peer Fin Info'!$D$11:$R$20,14,FALSE) -> 3732202 | K29: =VLOOKUP($D29,'Peer Fin Info'!$D$11:$R$20,15,FALSE) -> 3667419 | M29: =VLOOKUP($D29,'Peer Fin Info'!$D$11:$R$20,5,FALSE) -> 385476 | N29: =VLOOKUP($D29,'Peer Fin Info'!$D$11:$R$20,6,FALSE) -> 148227 | O29: =VLOOKUP($D29,'Peer Fin Info'!$D$11:$R$20,7,FALSE) -> 167528 | P29: =VLOOKUP($D29,'Peer Fin Info'!$D$11:$R$20,8,FALSE) -> 124251 | R29: =$K29/M29 -> 9.5140009 | S29: =$K29/N29 -> 24.741909 | T29: =$K29/O29 -> 21.891379 | U29: =J29/P29 -> 30.037601
C30: =C29+1 -> 3 | D30: Meta Platforms, Inc. | F30: =VLOOKUP($D30,'Peer Fin Info'!$D$11:$R$20,2,FALSE) -> META | G30: =VLOOKUP($D30,'Peer Fin Info'!$D$11:$R$20,3,FALSE) -> USA | I30: =VLOOKUP(F30,'Peer Mkt Info'!$E$10:$M$19,9,FALSE) -> 652.71 | J30: =VLOOKUP($D30,'Peer Fin Info'!$D$11:$R$20,14,FALSE) -> 1623799 | K30: =VLOOKUP($D30,'Peer Fin Info'!$D$11:$R$20,15,FALSE) -> 1630411 | M30: =VLOOKUP($D30,'Peer Fin Info'!$D$11:$R$20,5,FALSE) -> 189458 | N30: =VLOOKUP($D30,'Peer Fin Info'!$D$11:$R$20,6,FALSE) -> 82861 | O30: =VLOOKUP($D30,'Peer Fin Info'!$D$11:$R$20,7,FALSE) -> 100526 | P30: =VLOOKUP($D30,'Peer Fin Info'!$D$11:$R$20,8,FALSE) -> 58528 | R30: =$K30/M30 -> 8.6056593 | S30: =$K30/N30 -> 19.676458 | T30: =$K30/O30 -> 16.218799 | U30: =J30/P30 -> 27.743969
C31: =C30+1 -> 4 | D31: Oracle Corporation | F31: =VLOOKUP($D31,'Peer Fin Info'!$D$11:$R$20,2,FALSE) -> ORCL | G31: =VLOOKUP($D31,'Peer Fin Info'!$D$11:$R$20,3,FALSE) -> USA | I31: =VLOOKUP(F31,'Peer Mkt Info'!$E$10:$M$19,9,FALSE) -> 198.85 | J31: =VLOOKUP($D31,'Peer Fin Info'!$D$11:$R$20,14,FALSE) -> 541565 | K31: =VLOOKUP($D31,'Peer Fin Info'!$D$11:$R$20,15,FALSE) -> 646185 | M31: =VLOOKUP($D31,'Peer Fin Info'!$D$11:$R$20,5,FALSE) -> 61016 | N31: =VLOOKUP($D31,'Peer Fin Info'!$D$11:$R$20,6,FALSE) -> 20629 | O31: =VLOOKUP($D31,'Peer Fin Info'!$D$11:$R$20,7,FALSE) -> 22757 | P31: =VLOOKUP($D31,'Peer Fin Info'!$D$11:$R$20,8,FALSE) -> 15425 | R31: =$K31/M31 -> 10.590419 | S31: =$K31/N31 -> 31.324107 | T31: =$K31/O31 -> 28.394999 | U31: =J31/P31 -> 35.109562
C32: =C31+1 -> 5 | D32: Walmart Inc. | F32: =VLOOKUP($D32,'Peer Fin Info'!$D$11:$R$20,2,FALSE) -> WMT | G32: =VLOOKUP($D32,'Peer Fin Info'!$D$11:$R$20,3,FALSE) -> USA | I32: =VLOOKUP(F32,'Peer Mkt Info'!$E$10:$M$19,9,FALSE) -> 115.52 | J32: =VLOOKUP($D32,'Peer Fin Info'!$D$11:$R$20,14,FALSE) -> 930118 | K32: =VLOOKUP($D32,'Peer Fin Info'!$D$11:$R$20,15,FALSE) -> 987960 | M32: =VLOOKUP($D32,'Peer Fin Info'!$D$11:$R$20,5,FALSE) -> 703061 | N32: =VLOOKUP($D32,'Peer Fin Info'!$D$11:$R$20,6,FALSE) -> 32874 | O32: =VLOOKUP($D32,'Peer Fin Info'!$D$11:$R$20,7,FALSE) -> 46710 | P32: =VLOOKUP($D32,'Peer Fin Info'!$D$11:$R$20,8,FALSE) -> 23303 | R32: =$K32/M32 -> 1.4052266 | S32: =$K32/N32 -> 30.052929 | T32: =$K32/O32 -> 21.150931 | U32: =J32/P32 -> 39.914088
C33: =C32+1 -> 6 | D33: Costco Wholesale | F33: =VLOOKUP($D33,'Peer Fin Info'!$D$11:$R$20,2,FALSE) -> COST | G33: =VLOOKUP($D33,'Peer Fin Info'!$D$11:$R$20,3,FALSE) -> USA | I33: =VLOOKUP(F33,'Peer Mkt Info'!$E$10:$M$19,9,FALSE) -> 888.48 | J33: =VLOOKUP($D33,'Peer Fin Info'!$D$11:$R$20,14,FALSE) -> 392667 | K33: =VLOOKUP($D33,'Peer Fin Info'!$D$11:$R$20,15,FALSE) -> 385556 | M33: =VLOOKUP($D33,'Peer Fin Info'!$D$11:$R$20,5,FALSE) -> 208391 | N33: =VLOOKUP($D33,'Peer Fin Info'!$D$11:$R$20,6,FALSE) -> 10691 | O33: =VLOOKUP($D33,'Peer Fin Info'!$D$11:$R$20,7,FALSE) -> 13166 | P33: =VLOOKUP($D33,'Peer Fin Info'!$D$11:$R$20,8,FALSE) -> 8302 | R33: =$K33/M33 -> 1.8501567 | S33: =$K33/N33 -> 36.063605 | T33: =$K33/O33 -> 29.284217 | U33: =J33/P33 -> 47.29788
C34: =C33+1 -> 7 | D34: Target Corporation | F34: =VLOOKUP($D34,'Peer Fin Info'!$D$11:$R$20,2,FALSE) -> TGT | G34: =VLOOKUP($D34,'Peer Fin Info'!$D$11:$R$20,3,FALSE) -> USA | I34: =VLOOKUP(F34,'Peer Mkt Info'!$E$10:$M$19,9,FALSE) -> 96.97 | J34: =VLOOKUP($D34,'Peer Fin Info'!$D$11:$R$20,14,FALSE) -> 43909 | K34: =VLOOKUP($D34,'Peer Fin Info'!$D$11:$R$20,15,FALSE) -> 60128 | M34: =VLOOKUP($D34,'Peer Fin Info'!$D$11:$R$20,5,FALSE) -> 105242 | N34: =VLOOKUP($D34,'Peer Fin Info'!$D$11:$R$20,6,FALSE) -> 5301 | O34: =VLOOKUP($D34,'Peer Fin Info'!$D$11:$R$20,7,FALSE) -> 8398 | P34: =VLOOKUP($D34,'Peer Fin Info'!$D$11:$R$20,8,FALSE) -> 3763 | R34: =$K34/M34 -> 0.57133084 | S34: =$K34/N34 -> 11.342766 | T34: =$K34/O34 -> 7.1598 | U34: =J34/P34 -> 11.668615
C35: =C34+1 -> 8 | D35: Alibaba Group | F35: =VLOOKUP($D35,'Peer Fin Info'!$D$11:$R$20,2,FALSE) -> BABA | G35: =VLOOKUP($D35,'Peer Fin Info'!$D$11:$R$20,3,FALSE) -> China | I35: =VLOOKUP(F35,'Peer Mkt Info'!$E$10:$M$19,9,FALSE) -> 156.9 | J35: =VLOOKUP($D35,'Peer Fin Info'!$D$11:$R$20,14,FALSE) -> 374369 | K35: =VLOOKUP($D35,'Peer Fin Info'!$D$11:$R$20,15,FALSE) -> 194386 | M35: =VLOOKUP($D35,'Peer Fin Info'!$D$11:$R$20,5,FALSE) -> 1012055 | N35: =VLOOKUP($D35,'Peer Fin Info'!$D$11:$R$20,6,FALSE) -> 157058 | O35: =VLOOKUP($D35,'Peer Fin Info'!$D$11:$R$20,7,FALSE) -> 161586 | P35: =VLOOKUP($D35,'Peer Fin Info'!$D$11:$R$20,8,FALSE) -> 123354 | R35: =$K35/M35 -> 0.19207059 | S35: =$K35/N35 -> 1.2376702 | T35: =$K35/O35 -> 1.2029879 | U35: =J35/P35 -> 3.0349158
C36: =C35+1 -> 9 | D36: Apple Inc. | F36: =VLOOKUP($D36,'Peer Fin Info'!$D$11:$R$20,2,FALSE) -> AAPL | G36: =VLOOKUP($D36,'Peer Fin Info'!$D$11:$R$20,3,FALSE) -> USA | I36: =VLOOKUP(F36,'Peer Mkt Info'!$E$10:$M$19,9,FALSE) -> 278.03 | J36: =VLOOKUP($D36,'Peer Fin Info'!$D$11:$R$20,14,FALSE) -> 4108269 | K36: =VLOOKUP($D36,'Peer Fin Info'!$D$11:$R$20,15,FALSE) -> 4152229 | M36: =VLOOKUP($D36,'Peer Fin Info'!$D$11:$R$20,5,FALSE) -> 416161 | N36: =VLOOKUP($D36,'Peer Fin Info'!$D$11:$R$20,6,FALSE) -> 132729 | O36: =VLOOKUP($D36,'Peer Fin Info'!$D$11:$R$20,7,FALSE) -> 144427 | P36: =VLOOKUP($D36,'Peer Fin Info'!$D$11:$R$20,8,FALSE) -> 112010 | R36: =$K36/M36 -> 9.9774582 | S36: =$K36/N36 -> 31.28351 | T36: =$K36/O36 -> 28.749673 | U36: =J36/P36 -> 36.677698
C37: =C36+1 -> 10 | D37: Netflix, Inc. | F37: =VLOOKUP($D37,'Peer Fin Info'!$D$11:$R$20,2,FALSE) -> NFLX | G37: =VLOOKUP($D37,'Peer Fin Info'!$D$11:$R$20,3,FALSE) -> USA | I37: =VLOOKUP(F37,'Peer Mkt Info'!$E$10:$M$19,9,FALSE) -> 94.09 | J37: =VLOOKUP($D37,'Peer Fin Info'!$D$11:$R$20,14,FALSE) -> 399119 | K37: =VLOOKUP($D37,'Peer Fin Info'!$D$11:$R$20,15,FALSE) -> 404294.73 | M37: =VLOOKUP($D37,'Peer Fin Info'!$D$11:$R$20,5,FALSE) -> 39000.966 | N37: =VLOOKUP($D37,'Peer Fin Info'!$D$11:$R$20,6,FALSE) -> 12642.706 | O37: =VLOOKUP($D37,'Peer Fin Info'!$D$11:$R$20,7,FALSE) -> 25926.506 | P37: =VLOOKUP($D37,'Peer Fin Info'!$D$11:$R$20,8,FALSE) -> 8615.615 | R37: =$K37/M37 -> 10.366275 | S37: =$K37/N37 -> 31.978497 | T37: =$K37/O37 -> 15.593877 | U37: =J37/P37 -> 46.325074
C38: Low | R38: =MIN(R28:R37) -> 0.19207059 | S38: =MIN(S28:S37) -> 1.2376702 | T38: =MIN(T28:T37) -> 1.2029879 | U38: =MIN(U28:U37) -> 3.0349158
C39: Median | R39: =MEDIAN(R28:R37) -> 9.0598301 | S39: =MEDIAN(S28:S37) -> 28.84199 | T39: =MEDIAN(T28:T37) -> 21.096831 | U39: =MEDIAN(U28:U37) -> 34.505254
C40: Mean | R40: =AVERAGE(R28:R37) -> 6.5036598 | S40: =AVERAGE(S28:S37) -> 24.53325 | T40: =AVERAGE(T28:T37) -> 19.068939 | U40: =AVERAGE(U28:U37) -> 31.171035
C41: High | R41: =MAX(R28:R37) -> 11.964001 | S41: =MAX(S28:S37) -> 36.063605 | T41: =MAX(T28:T37) -> 29.284217 | U41: =MAX(U28:U37) -> 47.29788
D43: Amazon Inc. | F43: AMZN | G43: USA | I43: =DCF!E14 -> 226.19 | J43: =DCF!E43 -> 2424983 | K43: =DCF!E47 -> 3023721 | M43: =DCF!E27 -> 637959 | N43: =DCF!E31 -> 68593 | O43: =DCF!E29 -> 121388 | P43: ='Forecasted FS'!E56 -> 59248 | R43: =$K43/M43 -> 4.7396792 | S43: =$K43/N43 -> 44.082064 | T43: =$K43/O43 -> 24.909554 | U43: =J43/P43 -> 40.929365
C45: NOTE: Selection of peers is based on size and similarity of product offering and business risk to AMZN
C46: Source: PitchBook, Yahoo Finance
C47: https://my.pitchbook.com/dashboard | R47: AMZN Relative Valuation
C48: https://finance.yahoo.com/?guccounter=1 | R48: EV/Sales | S48: EV/EBIT | T48: EV/EBITDA | U48: P/E
P49: Low | R49: =(R38*E12+SUM(E14:E16))/E18 -> -44.41795 | S49: =(S38*F12+SUM(F14:F16))/F18 -> -47.928597 | T49: =(T38*G12+SUM(G14:G16))/G18 -> -48.150495 | U49: =(U38*H12)/H18 -> 16.772007
P50: Median | R50: =(R39*E12+SUM(E14:E16))/E18 -> 483.26296 | S50: =(S39*F12+SUM(F14:F16))/F18 -> 128.68395 | T50: =(T39*G12+SUM(G14:G16))/G18 -> 79.130389 | U50: =(U39*H12)/H18 -> 190.68812
P51: Mean | R51: =(R40*E12+SUM(E14:E16))/E18 -> 331.15663 | S51: =(S40*F12+SUM(F14:F16))/F18 -> 101.11661 | T51: =(T40*G12+SUM(G14:G16))/G18 -> 66.155933 | U51: =(U40*H12+SUM(H14:H16))/H18 -> 116.41484
P52: High | R52: =(R41*E12+SUM(E14:E16))/E18 -> 656.07723 | S52: =(S41*F12+SUM(F14:F16))/F18 -> 174.88787 | T52: =(T41*G12+SUM(G14:G16))/G18 -> 131.51332 | U52: =(U41*H12)/H18 -> 261.38465
...

Sheet Reg. Beta
C3: Beta Buildup Based on Regression Method
C4: In USD, unless told otherwise
C8: Date | D8: S&P 500 | E8: AMZN | F8: S&P Returns (%) | G8: AMZN Returns (%) | I8: NOTE:
C9: 44197 | D9: 3714.24 | E9: 160.31 | I9: Equity Beta construction is based on 5 year monthly returns of AMZN and S&P 500
C10: 44228 | D10: 3811.15 | E10: 154.65 | F10: =D10/D9-1 -> 0.026091475 | G10: =E10/E9-1 -> -0.035306593 | I10: Prices are based on adjusted at closing
C11: 44256 | D11: 3972.89 | E11: 154.7 | F11: =D11/D10-1 -> 0.042438634 | G11: =E11/E10-1 -> 0.0003233107
C12: 44287 | D12: 4181.17 | E12: 173.37 | F12: =D12/D11-1 -> 0.052425313 | G12: =E12/E11-1 -> 0.1206852 | I12: Beta Calculations
C13: 44317 | D13: 4204.11 | E13: 161.15 | F13: =D13/D12-1 -> 0.0054865026 | G13: =E13/E12-1 -> -0.07048509 | I13: AMZN Standard Deviation | J13: =_xlfn.STDEV.S(G10:G68) -> 0.090178662
C14: 44348 | D14: 4297.5 | E14: 172.01 | F14: =D14/D13-1 -> 0.022213976 | G14: =E14/E13-1 -> 0.06739063 | I14: S&P 500 Standard Deviation | J14: =_xlfn.STDEV.S(F10:F68) -> 0.043812395
C15: 44378 | D15: 4395.26 | E15: 166.38 | F15: =D15/D14-1 -> 0.022748109 | G15: =E15/E14-1 -> -0.032730655 | I15: Correlation Coefficient | J15: =CORREL(F10:F68,G10:G68) -> 0.66913721
C16: 44409 | D16: 4522.68 | E16: 173.54 | F16: =D16/D15-1 -> 0.028990321 | G16: =E16/E15-1 -> 0.043034019 | I16: Equity Beta | J16: =J15*J13/J14 -> 1.3772792 | K16: =SLOPE(G10:G68,F10:F68) -> 1.3772792
C17: 44440 | D17: 4307.54 | E17: 164.25 | F17: =D17/D16-1 -> -0.04756914 | G17: =E17/E16-1 -> -0.053532327
C18: 44470 | D18: 4605.38 | E18: 168.62 | F18: =D18/D17-1 -> 0.069143873 | G18: =E18/E17-1 -> 0.026605784 | I18: Source: Yahoo Finance
C19: 44501 | D19: 4567 | E19: 175.35 | F19: =D19/D18-1 -> -0.0083337314 | G19: =E19/E18-1 -> 0.039912229 | I19: https://finance.yahoo.com/quote/AMZN/history/?filter=history&frequency=1mo&period1=1607455486&period2=1765221833
C20: 44531 | D20: 4766.18 | E20: 166.72 | F20: =D20/D19-1 -> 0.043612875 | G20: =E20/E19-1 -> -0.049215854 | I20: https://finance.yahoo.com/quote/%5EGSPC/history/?period1=1609459200&period2=1767225600&interval=1mo&filter=history&frequency=1mo&includeAdjustedClose=true
C21: 44562 | D21: 4515.55 | E21: 149.57 | F21: =D21/D20-1 -> -0.052585089 | G21: =E21/E20-1 -> -0.10286708
C22: 44593 | D22: 4373.94 | E22: 153.56 | F22: =D22/D21-1 -> -0.031360521 | G22: =E22/E21-1 -> 0.026676473
C23: 44621 | D23: 4530.41 | E23: 163 | F23: =D23/D22-1 -> 0.035773239 | G23: =E23/E22-1 -> 0.061474342
C24: 44652 | D24: 4131.93 | E24: 124.28 | F24: =D24/D23-1 -> -0.087956719 | G24: =E24/E23-1 -> -0.23754601
C25: 44682 | D25: 4132.15 | E25: 120.21 | F25: =D25/D24-1 -> 5.3243884e-05 | G25: =E25/E24-1 -> -0.032748632
C26: 44713 | D26: 3785.38 | E26: 106.21 | F26: =D26/D25-1 -> -0.083919993 | G26: =E26/E25-1 -> -0.11646286
C27: 44743 | D27: 4130.29 | E27: 134.95 | F27: =D27/D26-1 -> 0.091116348 | G27: =E27/E26-1 -> 0.27059599
C28: 44774 | D28: 3955 | E28: 126.77 | F28: =D28/D27-1 -> -0.042440119 | G28: =E28/E27-1 -> -0.060615043
C29: 44805 | D29: 3585.62 | E29: 113 | F29: =D29/D28-1 -> -0.093395702 | G29: =E29/E28-1 -> -0.10862191
C30: 44835 | D30: 3871.98 | E30: 102.44 | F30: =D30/D29-1 -> 0.079863455 | G30: =E30/E29-1 -> -0.093451327
C31: 44866 | D31: 4080.11 | E31: 96.54 | F31: =D31/D30-1 -> 0.05375286 | G31: =E31/E30-1 -> -0.05759469
C32: 44896 | D32: 3839.5 | E32: 84 | F32: =D32/D31-1 -> -0.058971449 | G32: =E32/E31-1 -> -0.12989434
... C68: 45992 | D68: 6870.4 | E68: 229.53 | F68: =D68/D67-1 -> 0.0031113622 | G68: =E68/E67-1 -> -0.015821971

Sheet Forecasted FS
C3: Forecasted Financial Statements
C4: Figures in USD millions, unless told otherwise
C8: Scenario | D8: =IF(Scenarios!D8=Scenarios!D9,Scenarios!C9,IF(Scenarios!D8=Scenarios!D10,Scenarios!C10,Scenarios!C11)) -> Base Case
C10: Forecasting Assumptions
E12: 2024 Actual | F12: 2025 | G12: 2026 | H12: 2027 | I12: 2028 | J12: 2029 | L12: NOTES:
C13: Comprehensive Income Statement items:
C14: Sales Forecasted | E14: =E37 -> 637959 | F14: =E14*(1+F15) -> 682616.13 | G14: =F14*(1+G15) -> 744051.58 | H14: =G14*(1+H15) -> 811016.22 | I14: =H14*(1+I15) -> 892117.85 | J14: =I14*(1+J15) -> 981329.63 | L14: First year based on HWMS model
C15: Sales Growth Forecasted | E15: ='Actuals FS'!D149 -> 0.10990892 | F15: =Scenarios!E17 -> 0.07 | G15: =Scenarios!F17 -> 0.09 | H15: =Scenarios!G17 -> 0.09 | I15: =Scenarios!H17 -> 0.1 | J15: =Scenarios!I17 -> 0.1 | L15: Following scenario assumptions. First year is an adjustment to the base revenue forecasted with HWMS model
